Workbook

Sheet 决策首页
A1: 优先级 | B1: 治理项 | C1: 最新结论 | D1: 规则源 / 关联 ToDo | E1: 状态
A2: P0 | B2: 唯一价格源 | C2: ='规则与待确认'!$C$3 | D2: R-02；To Do | E2: ='规则与待确认'!$D$3
A3: P0 | B3: AI权益与业务规则 | C3: ='规则与待确认'!$C$15 | D3: R-14；To Do | E3: ='规则与待确认'!$D$15
A4: P0 | B4: 唯一执行源 | C4: To Do 只维护任务、日期、Owner、依赖、验收、完成状态及关联 Rule ID | D4: To Do；全部执行任务 | E4: 已生效
A5: P0 | B5: 价格评审基线 | C5: ='规则与待确认'!$C$3 | D5: R-02；To Do | E5: ='规则与待确认'!$D$3
A6: P0 | B6: 价格层级 | C6: ='规则与待确认'!$C$4 | D6: R-03；To Do | E6: ='规则与待确认'!$D$4
A7: P0 | B7: 年购 | C7: ='规则与待确认'!$C$5 | D7: R-04；To Do | E7: ='规则与待确认'!$D$5
A8: P0 | B8: 首发与首购 | C8: ='规则与待确认'!$C$6 | D8: R-05；To Do | E8: ='规则与待确认'!$D$6
A9: P0 | B9: 充值 | C9: ='规则与待确认'!$C$14 | D9: R-13；To Do | E9: ='规则与待确认'!$D$14
A10: P0 | B10: 订阅积分 | C10: ='规则与待确认'!$C$10 | D10: R-09；To Do | E10: ='规则与待确认'!$D$10
A11: P0 | B11: 续费与保价 | C11: ='规则与待确认'!$C$8 | D11: R-07；To Do | E11: ='规则与待确认'!$D$8
A12: P0 | B12: 升级 | C12: ='规则与待确认'!$C$18 | D12: R-17；To Do | E12: ='规则与待确认'!$D$18
A13: P0 | B13: 支付异常与停单 | C13: ='规则与待确认'!$C$9 | D13: R-08；To Do | E13: ='规则与待确认'!$D$9
A14: P0 | B14: 退款、开票与法务 | C14: ='规则与待确认'!$C$24 | D14: R-23；To Do | E14: ='规则与待确认'!$D$24
A15: P1 | B15: Stage 2 | C15: ='规则与待确认'!$C$23 | D15: R-22；To Do | E15: ='规则与待确认'!$D$23
A16: P1 | B16: 对外命名 | C16: ='规则与待确认'!$C$2 | D16: R-01；To Do | E16: ='规则与待确认'!$D$2

Sheet C端完整定价
A1: D5 C端完整定价｜最新成果引用视图｜2026-09-18
A2: 唯一价格源：定价推演 （最终）；唯一AI权益源：AI 权益。本表不再维护旧标准/长期/首发独立价格。
A3: CNY价格与调优价格并列引用；页面采用列、实际开放档位和月/年范围待确认。历史订单按成交版本履约。
A4: 产品线 | B4: 档位 | C4: 用量倍数 | D4: 套餐积分/月 | E4: 积分拆分 | F4: 总积分/月 | G4: 登录赠分/一次 | H4: 月价(CNY) | I4: 年价(CNY) | J4: 调优月价 | K4: 调优年价 | L4: 调优首月价 | M4: 首月价(CNY) | N4: 状态 | O4: AI权益摘要 | P4: 来源 / 边界
A5: 社区版 | B5: 免费 | C5: 0 | D5: 0 | E5: 非月度套餐 | F5: 0 | G5: 300 | H5: 0 | I5: 0 | J5: 0 | K5: 0 | L5: 0 | M5: 0 | N5: 免费体验 | O5: 并发2；图片1K；视频480P；部分模型；不可商用 | P5: 登录赠300，365天；无充值资格
A6: 基础版 | B6: 入门 | C6: =$D$6/1000 | D6: ='定价推演 （最终）'!$F$3 | E6: 后台拆分待确认 | F6: =$D$6 | G6: 300 | H6: ='定价推演 （最终）'!$C$3 | I6: ='定价推演 （最终）'!$C$5 | J6: ='定价推演 （最终）'!$D$3 | K6: ='定价推演 （最终）'!$D$5 | L6: ='定价推演 （最终）'!$D$4 | M6: ='定价推演 （最终）'!$C$4 | N6: 价格源已确认；上架范围待确认 | O6: ='AI 权益'!$F$3 | P6: 价格与调优价格未合并；年费不是月费
A7: 基础版 | B7: 轻量 | C7: =$D$7/1000 | D7: ='定价推演 （最终）'!$F$6 | E7: 后台拆分待确认 | F7: =$D$7 | G7: 300 | H7: ='定价推演 （最终）'!$C$6 | I7: ='定价推演 （最终）'!$C$8 | J7: ='定价推演 （最终）'!$D$6 | K7: ='定价推演 （最终）'!$D$8 | L7: ='定价推演 （最终）'!$D$7 | M7: ='定价推演 （最终）'!$C$7 | N7: 价格源已确认；上架范围待确认 | O7: ='AI 权益'!$F$4 | P7: 价格与调优价格未合并；年费不是月费
A8: 基础版 | B8: 标准 | C8: =$D$8/1000 | D8: ='定价推演 （最终）'!$F$9 | E8: 后台拆分待确认 | F8: =$D$8 | G8: 300 | H8: ='定价推演 （最终）'!$C$9 | I8: ='定价推演 （最终）'!$C$11 | J8: ='定价推演 （最终）'!$D$9 | K8: ='定价推演 （最终）'!$D$11 | L8: ='定价推演 （最终）'!$D$10 | M8: ='定价推演 （最终）'!$C$10 | N8: 价格源已确认；上架范围待确认 | O8: ='AI 权益'!$F$5 | P8: 价格与调优价格未合并；年费不是月费
A9: 基础版 | B9: 旗舰 | C9: =$D$9/1000 | D9: ='定价推演 （最终）'!$F$12 | E9: 后台拆分待确认 | F9: =$D$9 | G9: 300 | H9: ='定价推演 （最终）'!$C$12 | I9: ='定价推演 （最终）'!$C$14 | J9: ='定价推演 （最终）'!$D$12 | K9: ='定价推演 （最终）'!$D$14 | L9: ='定价推演 （最终）'!$D$13 | M9: ='定价推演 （最终）'!$C$13 | N9: 价格源已确认；上架范围待确认 | O9: ='AI 权益'!$F$6 | P9: 价格与调优价格未合并；年费不是月费
A10: 专业版 | B10: 入门 | C10: =$D$10/1000 | D10: ='定价推演 （最终）'!$F$15 | E10: 后台拆分待确认 | F10: =$D$10 | G10: 300 | H10: ='定价推演 （最终）'!$C$15 | I10: ='定价推演 （最终）'!$C$17 | J10: ='定价推演 （最终）'!$D$15 | K10: ='定价推演 （最终）'!$D$17 | L10: ='定价推演 （最终）'!$D$16 | M10: ='定价推演 （最终）'!$C$16 | N10: 价格源已确认；上架范围待确认 | O10: ='AI 权益'!$F$7 | P10: 价格与调优价格未合并；年费不是月费
A11: 专业版 | B11: 轻量 | C11: =$D$11/1000 | D11: ='定价推演 （最终）'!$F$18 | E11: 后台拆分待确认 | F11: =$D$11 | G11: 300 | H11: ='定价推演 （最终）'!$C$18 | I11: ='定价推演 （最终）'!$C$20 | J11: ='定价推演 （最终）'!$D$18 | K11: ='定价推演 （最终）'!$D$20 | L11: ='定价推演 （最终）'!$D$19 | M11: ='定价推演 （最终）'!$C$19 | N11: 价格源已确认；上架范围待确认 | O11: ='AI 权益'!$F$8 | P11: 价格与调优价格未合并；年费不是月费
A12: 专业版 | B12: 标准 | C12: =$D$12/1000 | D12: ='定价推演 （最终）'!$F$21 | E12: 后台拆分待确认 | F12: =$D$12 | G12: 300 | H12: ='定价推演 （最终）'!$C$21 | I12: ='定价推演 （最终）'!$C$23 | J12: ='定价推演 （最终）'!$D$21 | K12: ='定价推演 （最终）'!$D$23 | L12: ='定价推演 （最终）'!$D$22 | M12: ='定价推演 （最终）'!$C$22 | N12: 价格源已确认；上架范围待确认 | O12: ='AI 权益'!$F$9 | P12: 价格与调优价格未合并；年费不是月费
A13: 专业版 | B13: 旗舰 | C13: =$D$13/1000 | D13: ='定价推演 （最终）'!$F$24 | E13: 后台拆分待确认 | F13: =$D$13 | G13: 300 | H13: ='定价推演 （最终）'!$C$24 | I13: ='定价推演 （最终）'!$C$26 | J13: ='定价推演 （最终）'!$D$24 | K13: ='定价推演 （最终）'!$D$26 | L13: ='定价推演 （最终）'!$D$25 | M13: ='定价推演 （最终）'!$C$25 | N13: 价格源已确认；上架范围待确认 | O13: ='AI 权益'!$F$10 | P13: 价格与调优价格未合并；年费不是月费
A14: AI权益对照｜自动引用最新权益，协作项目数尚未上线
A15: 方案 | B15: 并发任务 | C15: 图片分辨率 | D15: 视频分辨率 | E15: 模型 | F15: 商用 | G15: 充值常态赠送 | H15: 充值有效期 | I15: AI增强/放大 | J15: 分享下载 | K15: 协作项目数（未上线） | L15: 开业活动原文 | M15: 活动计算状态
A16: ='AI 权益'!$A$3 | B16: ='AI 权益'!$B$3 | C16: ='AI 权益'!$C$3 | D16: ='AI 权益'!$D$3 | E16: ='AI 权益'!$E$3 | F16: ='AI 权益'!$F$3 | G16: ='AI 权益'!$G$3 | H16: ='AI 权益'!$H$3 | I16: ='AI 权益'!$I$3 | J16: ='AI 权益'!$L$3 | K16: ='AI 权益'!$M$3 | L16: ='AI 权益'!$N$3 | M16: 总比例/叠加待确认
A17: ='AI 权益'!$A$4 | B17: ='AI 权益'!$B$4 | C17: ='AI 权益'!$C$4 | D17: ='AI 权益'!$D$4 | E17: ='AI 权益'!$E$4 | F17: ='AI 权益'!$F$4 | G17: ='AI 权益'!$G$4 | H17: ='AI 权益'!$H$4 | I17: ='AI 权益'!$I$4 | J17: ='AI 权益'!$L$4 | K17: ='AI 权益'!$M$4 | L17: ='AI 权益'!$N$4 | M17: 总比例/叠加待确认
A18: ='AI 权益'!$A$5 | B18: ='AI 权益'!$B$5 | C18: ='AI 权益'!$C$5 | D18: ='AI 权益'!$D$5 | E18: ='AI 权益'!$E$5 | F18: ='AI 权益'!$F$5 | G18: ='AI 权益'!$G$5 | H18: ='AI 权益'!$H$5 | I18: ='AI 权益'!$I$5 | J18: ='AI 权益'!$L$5 | K18: ='AI 权益'!$M$5 | L18: ='AI 权益'!$N$5 | M18: 总比例/叠加待确认
A19: ='AI 权益'!$A$6 | B19: ='AI 权益'!$B$6 | C19: ='AI 权益'!$C$6 | D19: ='AI 权益'!$D$6 | E19: ='AI 权益'!$E$6 | F19: ='AI 权益'!$F$6 | G19: ='AI 权益'!$G$6 | H19: ='AI 权益'!$H$6 | I19: ='AI 权益'!$I$6 | J19: ='AI 权益'!$L$6 | K19: ='AI 权益'!$M$6 | L19: ='AI 权益'!$N$6 | M19: 总比例/叠加待确认
A20: ='AI 权益'!$A$7 | B20: ='AI 权益'!$B$7 | C20: ='AI 权益'!$C$7 | D20: ='AI 权益'!$D$7 | E20: ='AI 权益'!$E$7 | F20: ='AI 权益'!$F$7 | G20: ='AI 权益'!$G$7 | H20: ='AI 权益'!$H$7 | I20: ='AI 权益'!$I$7 | J20: ='AI 权益'!$L$7 | K20: ='AI 权益'!$M$7 | L20: ='AI 权益'!$N$7 | M20: 总比例/叠加待确认
A21: ='AI 权益'!$A$8 | B21: ='AI 权益'!$B$8 | C21: ='AI 权益'!$C$8 | D21: ='AI 权益'!$D$8 | E21: ='AI 权益'!$E$8 | F21: ='AI 权益'!$F$8 | G21: ='AI 权益'!$G$8 | H21: ='AI 权益'!$H$8 | I21: ='AI 权益'!$I$8 | J21: ='AI 权益'!$L$8 | K21: ='AI 权益'!$M$8 | L21: ='AI 权益'!$N$8 | M21: 总比例/叠加待确认
A22: ='AI 权益'!$A$9 | B22: ='AI 权益'!$B$9 | C22: ='AI 权益'!$C$9 | D22: ='AI 权益'!$D$9 | E22: ='AI 权益'!$E$9 | F22: ='AI 权益'!$F$9 | G22: ='AI 权益'!$G$9 | H22: ='AI 权益'!$H$9 | I22: ='AI 权益'!$I$9 | J22: ='AI 权益'!$L$9 | K22: ='AI 权益'!$M$9 | L22: ='AI 权益'!$N$9 | M22: 总比例/叠加待确认
A23: 下一行为专业版旗舰；协作项目数均为未上线能力，不作为当前可用承诺。分享链接一栏源表为空，不补写权限。
A24: ='AI 权益'!$A$10 | B24: ='AI 权益'!$B$10 | C24: ='AI 权益'!$C$10 | D24: ='AI 权益'!$D$10 | E24: ='AI 权益'!$E$10 | F24: ='AI 权益'!$F$10 | G24: ='AI 权益'!$G$10 | H24: ='AI 权益'!$H$10 | I24: ='AI 权益'!$I$10 | J24: ='AI 权益'!$L$10 | K24: ='AI 权益'!$M$10 | L24: ='AI 权益'!$N$10 | M24: 总比例/叠加待确认
A25: 来源与配置索引｜不维护第二套价格输入
A26: 项目 | B26: 值/指向 | C26: 类型 | D26: 状态 | E26: 说明
A27: 价格源 | B27: 定价推演 （最终） | C27: 只读源 | D27: 最新成果 | E27: 原价C列、调优D列、积分F列；本轮不修改
A28: AI权益源 | B28: AI 权益 | C28: 只读源 | D28: 最新成果 | E28: 并发、图片/视频、模型、商用、充值、增强放大等均按源引用
A29: 页面价格列 | B29: 待确认 | C29: 发布配置 | D29: 待确认 | E29: 不擅自把调优列设为已批准订单价
A30: 开放周期 | B30: 待确认 | C30: 发布配置 | D30: 待确认 | E30: 原灰度仅单次月购；源表有年价不等于已开放
A31: 开放档位 | B31: 待确认 | C31: 发布配置 | D31: 待确认 | E31: 入门/轻量/标准/旗舰都有价格；实际服务端SKU名单待确认
A32: 首购资格 | B32: 待确认 | C32: 配置 | D32: 待确认 | E32: 首月金额已列；资格和跨版本共享仍待确认
A33: 充值汇率 | B33: 20 | C33: 候选积分/元 | D33: 未确定 | E33: 引用未确定充值包中的当前候选；不能写成已确认新价
A34: 开业活动 | B34: AI 权益 M列 | C34: 来源 | D34: 计算口径待确认 | E34: 前三个月；总赠送/额外叠加及精确活动日期待确认
A35: 登录赠分 | B35: 300 | C35: 积分 | D35: 沿用确认 | E35: 下载Arco并登录；一次领取；365天有效
A36: 历史订单 | B36: 按成交版本 | C36: 履约 | D36: 保留 | E36: 不追溯改变已成交价、积分和有效期
A37: 软件价值 | B37: 最终价表L列 | C37: 内部观察 | D37: 非结算拆分 | E37: 不可直接作为混合升级折抵软件实付基数
A38: 套餐积分拆分 | B38: 待确认 | C38: 后台分类 | D38: 待确认 | E38: 总额度齐平，不额外叠加1000赠分
A39: 协作项目数 | B39: AI 权益 L列 | C39: 规划 | D39: 暂未上线 | E39: 基础3、专业6、团队/企业不限；不得标成已开放
A40: 分享链接 | B40: 源表空白 | C40: 权限 | D40: 待补充 | E40: 不把空白推断为支持或不支持
...

Sheet 首发与年付口径
A1: 方案 | B1: 月积分 | C1: 月价(CNY) | D1: 调优月价 | E1: 首月价(CNY) | F1: 调优首月价 | G1: 年价(CNY) | H1: 调优年价 | I1: 年购月均（调优） | J1: 发布状态 | K1: 来源与说明
A2: 基础版 入门 | B2: ='定价推演 （最终）'!$F$3 | C2: ='定价推演 （最终）'!$C$3 | D2: ='定价推演 （最终）'!$D$3 | E2: ='定价推演 （最终）'!$C$4 | F2: ='定价推演 （最终）'!$D$4 | G2: ='定价推演 （最终）'!$C$5 | H2: ='定价推演 （最终）'!$D$5 | I2: =$H$2/12 | J2: 采用列与周期待确认 | K2: 仅金额源；年购月均不是月付价格
A3: 基础版 轻量 | B3: ='定价推演 （最终）'!$F$6 | C3: ='定价推演 （最终）'!$C$6 | D3: ='定价推演 （最终）'!$D$6 | E3: ='定价推演 （最终）'!$C$7 | F3: ='定价推演 （最终）'!$D$7 | G3: ='定价推演 （最终）'!$C$8 | H3: ='定价推演 （最终）'!$D$8 | I3: =$H$3/12 | J3: 采用列与周期待确认 | K3: 仅金额源；年购月均不是月付价格
A4: 基础版 标准 | B4: ='定价推演 （最终）'!$F$9 | C4: ='定价推演 （最终）'!$C$9 | D4: ='定价推演 （最终）'!$D$9 | E4: ='定价推演 （最终）'!$C$10 | F4: ='定价推演 （最终）'!$D$10 | G4: ='定价推演 （最终）'!$C$11 | H4: ='定价推演 （最终）'!$D$11 | I4: =$H$4/12 | J4: 采用列与周期待确认 | K4: 仅金额源；年购月均不是月付价格
A5: 基础版 旗舰 | B5: ='定价推演 （最终）'!$F$12 | C5: ='定价推演 （最终）'!$C$12 | D5: ='定价推演 （最终）'!$D$12 | E5: ='定价推演 （最终）'!$C$13 | F5: ='定价推演 （最终）'!$D$13 | G5: ='定价推演 （最终）'!$C$14 | H5: ='定价推演 （最终）'!$D$14 | I5: =$H$5/12 | J5: 采用列与周期待确认 | K5: 仅金额源；年购月均不是月付价格
A6: 专业版 入门 | B6: ='定价推演 （最终）'!$F$15 | C6: ='定价推演 （最终）'!$C$15 | D6: ='定价推演 （最终）'!$D$15 | E6: ='定价推演 （最终）'!$C$16 | F6: ='定价推演 （最终）'!$D$16 | G6: ='定价推演 （最终）'!$C$17 | H6: ='定价推演 （最终）'!$D$17 | I6: =$H$6/12 | J6: 采用列与周期待确认 | K6: 仅金额源；年购月均不是月付价格
A7: 专业版 轻量 | B7: ='定价推演 （最终）'!$F$18 | C7: ='定价推演 （最终）'!$C$18 | D7: ='定价推演 （最终）'!$D$18 | E7: ='定价推演 （最终）'!$C$19 | F7: ='定价推演 （最终）'!$D$19 | G7: ='定价推演 （最终）'!$C$20 | H7: ='定价推演 （最终）'!$D$20 | I7: =$H$7/12 | J7: 采用列与周期待确认 | K7: 仅金额源；年购月均不是月付价格
A8: 专业版 标准 | B8: ='定价推演 （最终）'!$F$21 | C8: ='定价推演 （最终）'!$C$21 | D8: ='定价推演 （最终）'!$D$21 | E8: ='定价推演 （最终）'!$C$22 | F8: ='定价推演 （最终）'!$D$22 | G8: ='定价推演 （最终）'!$C$23 | H8: ='定价推演 （最终）'!$D$23 | I8: =$H$8/12 | J8: 采用列与周期待确认 | K8: 仅金额源；年购月均不是月付价格
A9: 专业版 旗舰 | B9: ='定价推演 （最终）'!$F$24 | C9: ='定价推演 （最终）'!$C$24 | D9: ='定价推演 （最终）'!$D$24 | E9: ='定价推演 （最终）'!$C$25 | F9: ='定价推演 （最终）'!$D$25 | G9: ='定价推演 （最终）'!$C$26 | H9: ='定价推演 （最终）'!$D$26 | I9: =$H$9/12 | J9: 采用列与周期待确认 | K9: 仅金额源；年购月均不是月付价格
A10: 首月资格 | J10: 待确认 | K10: 首月金额引用最新价表的首月行；正常月价引用月行。首购识别、旧用户资格、跨版本/周期共享及优惠活动叠加需产品确认。
A11: 购买周期 | J11: 待确认 | K11: 最新表已给出年价，但不等于灰度开放年购；本轮开放周期待确认。此前灰度为单次月购、无自动续费；若开放年购，沿用单次购买、积分按月发放。
A12: 年购发放 | J12: 年购开放时适用 | K12: 按积分月发放；不把年总额一次发放；不自动续费

Sheet 定价推演 （最终）
A1: 订阅 plan｜最终定价
A2: plan | B2: 计费 | C2: 价格(CNY) | D2: 调优价格(CNY) | E2: 价格(USD) | F2: 含credit | G2: 单credit(USD) | H2: 实际折扣(vs充值包) | I2: 年费 | J2: 对比上一档 | K2: 倒推软件价值计算口径 | L2: 倒推软件价值(CNY)
A3: 基础版 入门(小杯） | B3: 月 | C3: 49 | D3: 49 | E3: =C3/6.8 | F3: 1000 | G3: =E3/F3 | H3: =C3/F3/0.05-1 | I3: =C3*12
A4: 基础版 入门 | B4: 首月 | C4: 39 | D4: 39 | E4: =C4/6.8 | F4: =F3 | G4: =E4/F4 | H4: =C4/F4/0.05-1 | I4: =C4/C3
A5: 基础版 入门 | B5: 年 | C5: 399 | D5: 399 | E5: =C5/6.8 | F5: =F3*12 | G5: =E5/F5 | H5: =C5/F5/0.05-1 | I5: =C5/C3/12
A6: 基础版 轻量（中杯） | B6: 月 | C6: 129 | D6: 129 | E6: =C6/6.8 | F6: 2700 | G6: =E6/F6 | H6: =C6/F6/0.05-1 | I6: =C6*12 | J6: =G6/G3
A7: 基础版 轻量 | B7: 首月 | C7: 99 | D7: 99 | E7: =C7/6.8 | F7: =F6 | G7: =E7/F7 | H7: =C7/F7/0.05-1 | I7: =C7/C6
A8: 基础版 轻量 | B8: 年 | C8: 999 | D8: 999 | E8: =C8/6.8 | F8: =F6*12 | G8: =E8/F8 | H8: =C8/F8/0.05-1 | I8: =C8/C6/12 | J8: =G8/G5
A9: 基础版 标准（大杯） | B9: 月 | C9: 269 | D9: 269 | E9: =C9/6.8 | F9: 6000 | G9: =E9/F9 | H9: =C9/F9/0.05-1 | I9: =C9*12 | J9: =G9/G6
A10: 基础版 标准 | B10: 首月 | C10: 199 | D10: 199 | E10: =C10/6.8 | F10: =F9 | G10: =E10/F10 | H10: =C10/F10/0.05-1 | I10: =C10/C9
A11: 基础版 标准 | B11: 年 | C11: 1999 | D11: 1999 | E11: =C11/6.8 | F11: =F9*12 | G11: =E11/F11 | H11: =C11/F11/0.05-1 | I11: =C11/C9/12 | J11: =G11/G8
A12: 基础版 旗舰（超大杯） | B12: 月 | C12: 569 | D12: 569 | E12: =C12/6.8 | F12: 13000 | G12: =E12/F12 | H12: =C12/F12/0.05-1 | I12: =C12*12 | J12: =G12/G9
A13: 基础版 旗舰 | B13: 首月 | C13: 449 | D13: 449 | E13: =C13/6.8 | F13: =F12 | G13: =E13/F13 | H13: =C13/F13/0.05-1 | I13: =C13/C12
A14: 基础版 旗舰 | B14: 年 | C14: 3999 | D14: 3999 | E14: =C14/6.8 | F14: =F12*12 | G14: =E14/F14 | H14: =C14/F14/0.05-1 | I14: =C14/C12/12 | J14: =G14/G11
A15: 专业版 入门 | B15: 月 | C15: 200 | D15: 200 | F15: =F3 | K15: 调优价格 − 基础版入门·月价格 | L15: =D15-C3
A16: 专业版 入门 | B16: 首月 | C16: 200 | D16: 189 | F16: =F4 | K16: 调优价格 − 基础版入门·首月价格 | L16: =D16-C4
A17: 专业版 入门 | B17: 年 | C17: 1920 | D17: 1920 | F17: =F5 | K17: 调优价格 − 基础版入门·年价格 | L17: =D17-C5
A18: 专业版 轻量 | B18: 月 | C18: 280 | D18: 279 | F18: =F6 | K18: 调优价格 − 基础版轻量·月价格 | L18: =D18-C6
A19: 专业版 轻量 | B19: 首月 | C19: 250 | D19: 249 | F19: =F7 | K19: 调优价格 − 基础版轻量·首月价格 | L19: =D19-C7
A20: 专业版 轻量 | B20: 年 | C20: 2520 | D20: 2499 | F20: =F8 | K20: 调优价格 − 基础版轻量·年价格 | L20: =D20-C8
A21: 专业版 标准 | B21: 月 | C21: 420 | D21: 419 | F21: =F9 | K21: 调优价格 − 基础版标准·月价格 | L21: =D21-C9
A22: 专业版 标准 | B22: 首月 | C22: 350 | D22: 349 | F22: =F10 | K22: 调优价格 − 基础版标准·首月价格 | L22: =D22-C10
A23: 专业版 标准 | B23: 年 | C23: 3520 | D23: 3499 | F23: =F11 | K23: 调优价格 − 基础版标准·年价格 | L23: =D23-C11
A24: 专业版 旗舰 | B24: 月 | C24: 720 | D24: 719 | F24: =F12 | K24: 调优价格 − 基础版旗舰·月价格 | L24: =D24-C12
A25: 专业版 旗舰 | B25: 首月 | C25: 600 | D25: 599 | F25: =F13 | K25: 调优价格 − 基础版旗舰·首月价格 | L25: =D25-C13
A26: 专业版 旗舰 | B26: 年 | C26: 5520 | D26: 5499 | F26: =F14 | K26: 调优价格 − 基础版旗舰·年价格 | L26: =D26-C14

Sheet AI 权益
A1: 公开名称 | B1: 并发任务 | C1: 图片分辨率 | D1: 视频分辨率 | E1: 模型 | F1: 商用 | G1: 充值赠送 | H1: 充值有效期 | I1: AI 增强、放大功能（Arco内） | J1: AI 增强、放大功能（Render 内） | K1: 分享链接 | L1: 分享下载 | M1: 协作项目数（暂未上线） | N1: 开业活动（前三个月）
A2: 社区版 | B2: 2 | C2: 1k | D2: 480 P | E2: 部分 | F2: 不可商用 | G2: 不可充值 | I2: 消耗积分 | J2: 不支持 | L2: 不可管理 | M2: 1
A3: 基础版 入门 | B3: 4 | C3: 2k | D3: 720 P | E3: 全部 | F3: AI生成可商用 | G3: 标准价格 | H3: 90天 | I3: 消耗积分 | J3: 不支持 | L3: 下载管理 | M3: 3 | N3: 充值赠送30%
A4: 基础版 轻量 | B4: 6 | C4: 4K | D4: 4K | E4: 全部 | F4: AI生成可商用 | G4: 标准价格 | H4: 90天 | I4: 消耗积分 | J4: 不支持 | L4: 下载管理 | M4: 3 | N4: 充值赠送30%
A5: 基础版 标准 | B5: 10 | C5: 4K | D5: 4K | E5: 全部 | F5: AI生成可商用 | G5: 额外赠送10% | H5: 90天 | I5: 消耗积分 | J5: 不支持 | L5: 下载管理 | M5: 3 | N5: 充值赠送40%
A6: 基础版 旗舰 | B6: 不限 | C6: 4K | D6: 4K | E6: 全部 | F6: AI生成可商用 | G6: 额外赠送10% | H6: 90天 | I6: 消耗积分 | J6: 不支持 | L6: 下载管理 | M6: 3 | N6: 充值赠送40%
A7: 专业版 入门 | B7: 4 | C7: 4K | D7: 4K | E7: 全部 | F7: 全部可商用 | G7: 额外赠送10% | H7: 180天 | I7: 消耗积分 | J7: 不消耗积分 | L7: 下载管理 | M7: 6 | N7: 充值赠送40%
A8: 专业版 轻量 | B8: 6 | C8: 4K | D8: 4K | E8: 全部 | F8: 全部可商用 | G8: 额外赠送10% | H8: 180天 | I8: 消耗积分 | J8: 不消耗积分 | L8: 下载管理 | M8: 6 | N8: 充值赠送40%
A9: 专业版 标准 | B9: 10 | C9: 4K | D9: 4K | E9: 全部 | F9: 全部可商用 | G9: 额外赠送20% | H9: 180天 | I9: 消耗积分 | J9: 不消耗积分 | L9: 下载管理 | M9: 6 | N9: 充值赠送50%
A10: 专业版 旗舰 | B10: 不限 | C10: 4K | D10: 4K | E10: 全部 | F10: 全部可商用 | G10: 额外赠送20% | H10: 180天 | I10: 消耗积分 | J10: 不消耗积分 | L10: 下载管理 | M10: 6 | N10: 充值赠送50%
A11: 团队版 | B11: 10 | C11: 4K | D11: 4K | E11: 全部 | F11: 全部可商用 | G11: 企业价格 | H11: 365天 | M11: 不限 | N11: 充值赠送50%
A12: 基础席位 | I12: 消耗积分 | J12: 消耗积分
A13: 专业席位 | I13: 消耗积分 | J13: 不消耗积分
A14: 企业版 | B14: 不限 | C14: 4K | D14: 4K | E14: 全部 | F14: 全部可商用 | G14: 企业价格 | H14: 365天 | M14: 不限 | N14: 充值赠送60%
A15: 基础席位 | I15: 消耗积分 | J15: 消耗积分
A16: 专业席位 | I16: 消耗积分 | J16: 不消耗积分
A17: 教育版 | B17: 4 | C17: 4K | D17: 4K | E17: 全部 | F17: 不可商用 | G17: 教育优惠 | H17: 180天 | I17: 消耗积分 | J17: 不消耗积分 | L17: 不可管理 | M17: 3 | N17: 教育优惠

Sheet C端充值包（未确定版）
A1: 适用版本 | B1: 单笔金额规则 | C1: 候选汇率(积分/元) | D1: 常态赠送（权益源） | E1: 前三个月活动（权益源） | F1: 活动计算口径 | G1: 有效期（权益源） | H1: 基础积分算法（待定） | I1: 赠送积分算法 | J1: 购买资格 | K1: 批次处理 | L1: 状态 | M1: 关联To Do
A2: ='AI 权益'!$A$3 | B2: 50元起；50的倍数（沿此前规则，最终待配置） | C2: 20 | D2: ='AI 权益'!$G$3 | E2: ='AI 权益'!$N$3 | F2: 总赠送/额外叠加待确认 | G2: ='AI 权益'!$H$3 | H2: 金额×确认后汇率；20为候选 | I2: 基础积分×确认后的适用赠送比例 | J2: 有效会员；社区不可充值 | K2: 按充值时权益记录；到期冻结不延长原期限 | L2: 未确定充值报价；常态权益已引用 | M2: DEC-17；MKT-R01～04
A3: ='AI 权益'!$A$4 | B3: 50元起；50的倍数（沿此前规则，最终待配置） | C3: 20 | D3: ='AI 权益'!$G$4 | E3: ='AI 权益'!$N$4 | F3: 总赠送/额外叠加待确认 | G3: ='AI 权益'!$H$4 | H3: 金额×确认后汇率；20为候选 | I3: 基础积分×确认后的适用赠送比例 | J3: 有效会员；社区不可充值 | K3: 按充值时权益记录；到期冻结不延长原期限 | L3: 未确定充值报价；常态权益已引用 | M3: DEC-17；MKT-R01～04
A4: ='AI 权益'!$A$5 | B4: 50元起；50的倍数（沿此前规则，最终待配置） | C4: 20 | D4: ='AI 权益'!$G$5 | E4: ='AI 权益'!$N$5 | F4: 总赠送/额外叠加待确认 | G4: ='AI 权益'!$H$5 | H4: 金额×确认后汇率；20为候选 | I4: 基础积分×确认后的适用赠送比例 | J4: 有效会员；社区不可充值 | K4: 按充值时权益记录；到期冻结不延长原期限 | L4: 未确定充值报价；常态权益已引用 | M4: DEC-17；MKT-R01～04
A5: ='AI 权益'!$A$6 | B5: 50元起；50的倍数（沿此前规则，最终待配置） | C5: 20 | D5: ='AI 权益'!$G$6 | E5: ='AI 权益'!$N$6 | F5: 总赠送/额外叠加待确认 | G5: ='AI 权益'!$H$6 | H5: 金额×确认后汇率；20为候选 | I5: 基础积分×确认后的适用赠送比例 | J5: 有效会员；社区不可充值 | K5: 按充值时权益记录；到期冻结不延长原期限 | L5: 未确定充值报价；常态权益已引用 | M5: DEC-17；MKT-R01～04
A6: ='AI 权益'!$A$7 | B6: 50元起；50的倍数（沿此前规则，最终待配置） | C6: 20 | D6: ='AI 权益'!$G$7 | E6: ='AI 权益'!$N$7 | F6: 总赠送/额外叠加待确认 | G6: ='AI 权益'!$H$7 | H6: 金额×确认后汇率；20为候选 | I6: 基础积分×确认后的适用赠送比例 | J6: 有效会员；社区不可充值 | K6: 按充值时权益记录；到期冻结不延长原期限 | L6: 未确定充值报价；常态权益已引用 | M6: DEC-17；MKT-R01～04
A7: ='AI 权益'!$A$8 | B7: 50元起；50的倍数（沿此前规则，最终待配置） | C7: 20 | D7: ='AI 权益'!$G$8 | E7: ='AI 权益'!$N$8 | F7: 总赠送/额外叠加待确认 | G7: ='AI 权益'!$H$8 | H7: 金额×确认后汇率；20为候选 | I7: 基础积分×确认后的适用赠送比例 | J7: 有效会员；社区不可充值 | K7: 按充值时权益记录；到期冻结不延长原期限 | L7: 未确定充值报价；常态权益已引用 | M7: DEC-17；MKT-R01～04
A8: ='AI 权益'!$A$9 | B8: 50元起；50的倍数（沿此前规则，最终待配置） | C8: 20 | D8: ='AI 权益'!$G$9 | E8: ='AI 权益'!$N$9 | F8: 总赠送/额外叠加待确认 | G8: ='AI 权益'!$H$9 | H8: 金额×确认后汇率；20为候选 | I8: 基础积分×确认后的适用赠送比例 | J8: 有效会员；社区不可充值 | K8: 按充值时权益记录；到期冻结不延长原期限 | L8: 未确定充值报价；常态权益已引用 | M8: DEC-17；MKT-R01～04
A9: ='AI 权益'!$A$10 | B9: 50元起；50的倍数（沿此前规则，最终待配置） | C9: 20 | D9: ='AI 权益'!$G$10 | E9: ='AI 权益'!$N$10 | F9: 总赠送/额外叠加待确认 | G9: ='AI 权益'!$H$10 | H9: 金额×确认后汇率；20为候选 | I9: 基础积分×确认后的适用赠送比例 | J9: 有效会员；社区不可充值 | K9: 按充值时权益记录；到期冻结不延长原期限 | L9: 未确定充值报价；常态权益已引用 | M9: DEC-17；MKT-R01～04
A10: ='AI 权益'!$A$11 | B10: 金额条件待销售/产品确认 | C10: 未确定 | D10: ='AI 权益'!$G$11 | E10: ='AI 权益'!$N$11 | F10: 独立配置，不套C端 | G10: ='AI 权益'!$H$11 | H10: 实际企业/教育汇率待确认 | I10: 实际企业/教育优惠待确认 | J10: 按对应渠道资格 | K10: 按订单承诺履约 | L10: 不继承旧500/5000阈值 | M10: DEC-17；MKT-P13～14
A11: ='AI 权益'!$A$14 | B11: 金额条件待销售/产品确认 | C11: 未确定 | D11: ='AI 权益'!$G$14 | E11: ='AI 权益'!$N$14 | F11: 独立配置，不套C端 | G11: ='AI 权益'!$H$14 | H11: 实际企业/教育汇率待确认 | I11: 实际企业/教育优惠待确认 | J11: 按对应渠道资格 | K11: 按订单承诺履约 | L11: 不继承旧500/5000阈值 | M11: DEC-17；MKT-P13～14
A12: ='AI 权益'!$A$17 | B12: 金额条件待销售/产品确认 | C12: 未确定 | D12: ='AI 权益'!$G$17 | E12: ='AI 权益'!$N$17 | F12: 独立配置，不套C端 | G12: ='AI 权益'!$H$17 | H12: 实际企业/教育汇率待确认 | I12: 实际企业/教育优惠待确认 | J12: 按对应渠道资格 | K12: 按订单承诺履约 | L12: 不继承旧500/5000阈值 | M12: DEC-17；MKT-P13～14

Sheet B端完整定价
A1: 记录类型 | B1: 产品 | C1: 席位 / 规则 | D1: 席位定义 | E1: 版本基础权益 | F1: 版本独有高阶权益 | G1: 积分权益 | H1: 市场标准价 | I1: 折扣区间 | J1: 首发售价 | K1: 客群 | L1: 特殊情况 / 政策
A2: 原则 | B2: B 端 | C2: 本轮处理 | L2: 保留既有B端席位评审报价；AI并发、充值和增强/放大规则以AI权益最新成果为准；具体合同价和迁移仍待销售/财务确认。
A3: 席位 | B3: 企业版 | C3: 专业席位 | D3: 一个账号在同一台机器上可同时登录 Arco、LITE、渲染器团队版，实现在线串流 | E3: Arco；LITE；渲染器团队版 | F3: 多团队、TOKEN 额度管理（标准席位和基础席位后台统一管理额度分配，共享 AI 积分池）、SSO、权限控制、API 接口能力（开发中） | G3: 40,000 积分/席，一年有效 | H3: 5000 | I3: 7–7.5 折 | J3: =TEXT(H3*0.7,"#,##0")&"–"&TEXT(H3*0.75,"#,##0")&" 元/席/年" | K3: 大型客户 | L3: 首发价为底价；企业版无平台费，按人数席位收费；内部可将积分与软件、协作及管理价值拆账
A4: 席位 | B4: 企业版 | C4: 基础席位 | D4: 一个账号在同一台机器上可同时登录 Arco、LITE（免费功能权益）、渲染器（免费功能权益），通过线下导入导出实现串流 | E4: Arco；LITE—仅限免费功能权益；渲染器—仅限免费功能权益 | F4: Arco 多团队管理协作能力（开发中） | G4: 22,000 积分/席，一年有效 | H4: 1500 | I4: 6–6.5 折 | J4: =TEXT(H4*0.6,"#,##0")&"–"&TEXT(H4*0.65,"#,##0")&" 元/席/年" | K4: 大型客户 | L4: 基础席位溢价主要来自积分池化、协作和管理；企业版无平台费；最低席位数暂未确定
A5: 席位 | B5: 团队版 | C5: 专业席位 | D5: 一个账号在同一台机器上可同时登录 Arco、LITE、渲染器团队版，实现在线串流 | E5: Arco；LITE；渲染器团队版 | F5: Token 池化管理：标准席位和基础席位共享 AI 积分池 | G5: 25,000 积分/席，一年有效 | H5: 4000 | I5: 7–7.5 折 | J5: =TEXT(H5*0.7,"#,##0")&"–"&TEXT(H5*0.75,"#,##0")&" 元/席/年" | K5: 中小型客户 | L5: 首发价为底价；按人数席位收费；可仅续费渲染器（无积分）；续费按届时价格与折扣
A6: 席位 | B6: 团队版 | C6: 基础席位 | D6: 一个账号在同一台机器上可同时登录 Arco、LITE（免费功能权益）、渲染器（免费功能权益），通过线下导入导出实现串流 | E6: Arco；LITE—仅限免费功能权益；渲染器—仅限免费功能权益 | F6: Arco 单团队协作能力 | G6: 20,000 积分/席，一年有效 | H6: 1200 | I6: 6–6.5 折 | J6: =TEXT(H6*0.6,"#,##0")&"–"&TEXT(H6*0.65,"#,##0")&" 元/席/年" | K6: 中小型客户 | L6: 基础席位溢价主要来自积分池化与团队协作；不强调纯软件收入；最低席位数暂未确定
A7: 规则 | B7: B 端通用 | C7: 赠送 1–2 个月 | G7: 积分有效期仍为 12 个月；赠送月份不增加积分 | L7: 赠送的是渲染器高阶使用权限
A8: 规则 | B8: 团队版 / 企业版充值 | C8: 按企业价格配置 | D8: 旧金额阈值不再沿用 | E8: 企业汇率待确认 | F8: 按订单约定批次到期 | G8: 365天 | H8: 企业价格（待具体配置） | I8: 团队开业活动50% | J8: 企业开业活动60% | K8: 团队版 / 企业版 | L8: 活动日期与叠加规则待确认；AI权益为唯一权益源
A10: 规则 | B10: 积分归属 | C10: C / B 隔离 | G10: C 端个人积分不进入 B 端组织共享池 | L10: 个人积分与组织池隔离；C→B迁移须先确认席位、剩余价值折算、个人余额保留及生效流程。未有可执行折算公式，不套用C端A/B/C算法。
A11: 规则 | B11: 团队版 | C11: 仅渲染器续费 | G11: 无 AI 积分 | H11: 2400 | L11: 仅续费渲染器团队版；无 AI 积分；实际续费按届时有效价格及当期折扣，不延续首发底价

Sheet 成本与毛利
A1: 参数 / 场景 | B1: 单积分成本假设(元) | C1: 套餐积分/实付元 | D1: 单积分收入(元) | E1: 模型成本/收入 | F1: 模型层毛利率 | G1: 价格引用 | H1: 边界
A2: 治理说明 | G2: 最终定价C与D基础版相同 | H2: 0.0233为未核实历史假设；不含税、支付、软件和运营。不测未确定充值，不拆专业软件收入。
A3: 基础版 入门·月 | B3: 0.0233 | C3: ='定价推演 （最终）'!$F$3/'定价推演 （最终）'!$D$3 | D3: =1/$C$3 | E3: =$B$3*$C$3 | F3: =1-$E$3 | G3: 最终定价同档同周期 | H3: 仅假设测算；非实际毛利
A4: 基础版 入门·首月 | B4: 0.0233 | C4: ='定价推演 （最终）'!$F$4/'定价推演 （最终）'!$D$4 | D4: =1/$C$4 | E4: =$B$4*$C$4 | F4: =1-$E$4 | G4: 最终定价同档同周期 | H4: 仅假设测算；非实际毛利
A5: 基础版 入门·年 | B5: 0.0233 | C5: ='定价推演 （最终）'!$F$5/'定价推演 （最终）'!$D$5 | D5: =1/$C$5 | E5: =$B$5*$C$5 | F5: =1-$E$5 | G5: 最终定价同档同周期 | H5: 仅假设测算；非实际毛利
A6: 基础版 轻量·月 | B6: 0.0233 | C6: ='定价推演 （最终）'!$F$6/'定价推演 （最终）'!$D$6 | D6: =1/$C$6 | E6: =$B$6*$C$6 | F6: =1-$E$6 | G6: 最终定价同档同周期 | H6: 仅假设测算；非实际毛利
A7: 基础版 轻量·首月 | B7: 0.0233 | C7: ='定价推演 （最终）'!$F$7/'定价推演 （最终）'!$D$7 | D7: =1/$C$7 | E7: =$B$7*$C$7 | F7: =1-$E$7 | G7: 最终定价同档同周期 | H7: 仅假设测算；非实际毛利
A8: 基础版 轻量·年 | B8: 0.0233 | C8: ='定价推演 （最终）'!$F$8/'定价推演 （最终）'!$D$8 | D8: =1/$C$8 | E8: =$B$8*$C$8 | F8: =1-$E$8 | G8: 最终定价同档同周期 | H8: 仅假设测算；非实际毛利
A9: 基础版 标准·月 | B9: 0.0233 | C9: ='定价推演 （最终）'!$F$9/'定价推演 （最终）'!$D$9 | D9: =1/$C$9 | E9: =$B$9*$C$9 | F9: =1-$E$9 | G9: 最终定价同档同周期 | H9: 仅假设测算；非实际毛利
A10: 基础版 标准·首月 | B10: 0.0233 | C10: ='定价推演 （最终）'!$F$10/'定价推演 （最终）'!$D$10 | D10: =1/$C$10 | E10: =$B$10*$C$10 | F10: =1-$E$10 | G10: 最终定价同档同周期 | H10: 仅假设测算；非实际毛利
A11: 基础版 标准·年 | B11: 0.0233 | C11: ='定价推演 （最终）'!$F$11/'定价推演 （最终）'!$D$11 | D11: =1/$C$11 | E11: =$B$11*$C$11 | F11: =1-$E$11 | G11: 最终定价同档同周期 | H11: 仅假设测算；非实际毛利
A12: 基础版 旗舰·月 | B12: 0.0233 | C12: ='定价推演 （最终）'!$F$12/'定价推演 （最终）'!$D$12 | D12: =1/$C$12 | E12: =$B$12*$C$12 | F12: =1-$E$12 | G12: 最终定价同档同周期 | H12: 仅假设测算；非实际毛利
A13: 基础版 旗舰·首月 | B13: 0.0233 | C13: ='定价推演 （最终）'!$F$13/'定价推演 （最终）'!$D$13 | D13: =1/$C$13 | E13: =$B$13*$C$13 | F13: =1-$E$13 | G13: 最终定价同档同周期 | H13: 仅假设测算；非实际毛利
A14: 基础版 旗舰·年 | B14: 0.0233 | C14: ='定价推演 （最终）'!$F$14/'定价推演 （最终）'!$D$14 | D14: =1/$C$14 | E14: =$B$14*$C$14 | F14: =1-$E$14 | G14: 最终定价同档同周期 | H14: 仅假设测算；非实际毛利

Sheet 规则与待确认
A1: 规则 ID | B1: 规则域 | C1: 最新口径 | D1: 状态 | E1: 关联 ToDo ID | F1: 生效范围 / 决策点 | G1: 备注
A2: R-01 | B2: 命名与用量 | C2: 社区版；基础版、专业版各提供入门1000、轻量2700、标准6000、旗舰13000积分/月；不再沿用0x/1x/5x/10x及旧两档命名。 | D2: 名称与额度已确认；实际上架范围待确认 | E2: DEC-09～10、MKT-P01～08、BKL-03 | F2: 2026-09-18最新方案 | G2: 最新定价与AI权益为依据；四档有价格不等于全部已上架。
A3: R-02 | B3: 价格唯一来源 | C3: 价格数值只引用「定价推演 （最终）」；「C端完整定价」为引用展示，不再维护独立价格。C列价格与D列调优价格分别保留；页面最终采用哪列待确认。 | D3: 源表已确认；展示列待确认 | E3: DEC-01～06、DEC-11、MKT-P04～08 | F3: 2026-09-18最新方案 | G3: 2026-09-18用户指定最新成果；本轮源表不修改。
A4: R-03 | B4: 价格层级 | C4: 每档区分常规月价、首月价、年价；旧标准/长期/首发三套价格停止作为新方案依据。首月价仅首期，不永久锁价。 | D4: 按最新价表更新 | E4: DEC-04～05、MKT-P04 | F4: 2026-09-18最新方案 | G4: 年价是独立金额，不用统一八折或软件固定加价反推。
A5: R-04 | B5: 购买周期 | C5: 最新表已给出年价，但不等于灰度开放年购；本轮开放周期待确认。此前灰度为单次月购、无自动续费；若开放年购，沿用单次购买、积分按月发放。 | D5: 开放范围待确认 | E5: DEC-06、MKT-P05、REL-04 | F5: 2026-09-18最新方案 | G5: 未确认前不自动新增年付或自动续费入口。
A6: R-05 | B6: 首月优惠 | C6: 首月金额引用最新价表的首月行；正常月价引用月行。首购识别、旧用户资格、跨版本/周期共享及优惠活动叠加需产品确认。 | D6: 金额源已确认；资格待确认 | E6: DEC-07～08、MKT-P19 | F6: 2026-09-18最新方案 | G6: 不沿用首发结束后才启用首购、首购年价600/2200等旧规则。
A7: R-06 | B7: 开业活动与履约 | C7: AI权益列明前三个月活动：基础入门/轻量30%，基础标准/旗舰40%，专业入门/轻量40%，专业标准/旗舰50%；团队50%、企业60%。总赠送还是额外叠加、起止日和资格待确认。 | D7: 比例源已确认；计算口径待确认 | E7: MKT-P20、MKT-A01～A07 | F7: 2026-09-18最新方案 | G7: 不直接叠加常态赠送或已取消的公测额外20%；既有订单按原承诺履约。
A8: R-07 | B8: 续购与自动续费 | C8: 此前个人灰度为单次月购，提前续购到原周期结束后衔接，届时发积分，到期不自动续费。本次未取得自动续费开放确认，不沿用连续包月锁价。 | D8: 沿用最近确认；新开放范围待确认 | E8: DEC-18、MKT-P18、MKT-F02、REL-04 | F8: 2026-09-18最新方案 | G8: 历史自动续费订单单独处理；首月价不持续。
A9: R-08 | B9: 支付异常 | C9: 当前一次性购买区分未支付、支付结果未知、已支付待开通、已开通待发分；幂等与对账需真实联调。自动续费失败规则只适用于历史或后续实际开放的自动续费订单。 | D9: 待联调 | E9: DEC-12、MKT-P17、REL-04 | F9: 2026-09-18最新方案 | G9: 不得把文案或表格通过当成支付验收。
A10: R-09 | B10: 套餐积分额度 | C10: 同档基础版与专业版总积分齐平：1000/2700/6000/13000每月。年行12000/32400/72000/156000为年度总额，不是每月额度；后台付费/赠送拆分另确认。 | D10: 总额度已确认 | E10: DEC-20、MKT-P06～09 | F10: 2026-09-18最新方案 | G10: 不得额外给专业版叠加1000积分；前台不宣传未经确认的拆分。
A11: R-10 | B11: 积分发放与到期 | C11: 月购生效发当期积分，按积分月到期、不累计；提前续购在下一周期开始发放。开放年购时仍按月发，年总额不一次到账。积分月不等于自然月或固定30天。 | D11: 沿用已确认规则 | E11: DEC-20、PM-02、MKT-P09 | F11: 2026-09-18最新方案 | G11: 月末、闰年、时区与幂等需联调。
A12: R-11 | B12: 分账与扣减 | C12: 免费积分→月度方案积分→充值积分；同类最早到期优先。来源与批次独立记录，不把冻结余额计为可用。 | D12: 按最近母版口径同步 | E12: DEC-20、PM-02、MKT-P10 | F12: 2026-09-18最新方案 | G12: 替换旧全局最早到期及同日优先订阅的文案。
... A25: R-24 | B25: 停单与并发 | C25: 按AI权益配置并发：社区2；基础和专业各档4/6/10/不限；团队10、企业不限、教育4。并发是本版明确权益，不能再列为首发不做。紧急停单/回滚仍需验收。 | D25: 并发已确认；工程待验收 | E25: DEC-13、BKL-02 | F25: 2026-09-18最新方案 | G25: 不限不代表所有速率和服务治理限制均取消。

Sheet 升级与续费规则
A1: 场景 | B1: 生效时间 | C1: 新周期 / 到期日 | D1: 应付金额 | E1: 现有积分 | F1: 补发积分 | G1: 后续发放 | H1: 价格锁定 / 续费 | I1: 关联 ToDo | J1: 状态
A2: 社区版→已开放的基础/专业方案 | B2: 支付成功立即生效 | C2: 从购买日开始完整月或年周期 | D2: 按目标 SKU 当前完整周期价格支付 | E2: 无订阅积分继承问题 | F2: 按新购规则发首批积分 | G2: 从购买锚点按月发放 | H2: 首月优惠仅首期；次期价明确展示；年购单次支付不自动续费 | I2: MKT-P06～08 | J2: 新购；周期以实际开放配置为准
A3: A类｜基础版→专业版（月→月；目标额度不降低） | B3: 支付成功立即生效 | C3: 同周期：到期日及积分月发锚点不变 | D3: 应付＝（目标月价−当前月价）×原月周期剩余时长比例；按实际适用价格结算 | E3: 当前未用订阅积分保留；原到期日不变 | F3: 补发=向上取整[(目标月额度−当前月额度)×当前积分月剩余比例]；同档基础→专业为0；补发与旧积分原积分月末到期 | G3: 从原下一积分月起发完整目标月额度；年购仍逐月发放 | H3: 提前续购按R-07衔接；年路径仅在年购开放后启用 | I3: MKT-G01、MKT-G04 | J3: 规则适用已开放SKU；4档按实际额度比较，不使用旧1x/5x/10x
A4: A类｜基础版→专业版（年→年；目标额度不降低） | B4: 支付成功立即生效 | C4: 同周期：到期日及积分月发锚点不变 | D4: 应付＝（目标年价−当前年价）×原年周期剩余时长比例；按实际适用价格结算 | E4: 当前未用订阅积分保留；原到期日不变 | F4: 补发=向上取整[(目标月额度−当前月额度)×当前积分月剩余比例]；同档基础→专业为0；补发与旧积分原积分月末到期 | G4: 从原下一积分月起发完整目标月额度；年购仍逐月发放 | H4: 提前续购按R-07衔接；年路径仅在年购开放后启用 | I4: MKT-G03～G04 | J4: 规则适用已开放SKU；4档按实际额度比较，不使用旧1x/5x/10x
A5: A类｜专业版提升用量（月→月；含同时提额） | B5: 支付成功立即生效 | C5: 同周期：到期日及积分月发锚点不变 | D5: 应付＝（目标月价−当前月价）×原月周期剩余时长比例；按实际适用价格结算 | E5: 当前未用订阅积分保留；原到期日不变 | F5: 补发=向上取整[(目标月额度−当前月额度)×当前积分月剩余比例]；同档基础→专业为0；补发与旧积分原积分月末到期 | G5: 从原下一积分月起发完整目标月额度；年购仍逐月发放 | H5: 提前续购按R-07衔接；年路径仅在年购开放后启用 | I5: MKT-G02、MKT-G04 | J5: 规则适用已开放SKU；4档按实际额度比较，不使用旧1x/5x/10x
A6: A类｜专业版提升用量（年→年；含同时提额） | B6: 支付成功立即生效 | C6: 同周期：到期日及积分月发锚点不变 | D6: 应付＝（目标年价−当前年价）×原年周期剩余时长比例；按实际适用价格结算 | E6: 当前未用订阅积分保留；原到期日不变 | F6: 补发=向上取整[(目标月额度−当前月额度)×当前积分月剩余比例]；同档基础→专业为0；补发与旧积分原积分月末到期 | G6: 从原下一积分月起发完整目标月额度；年购仍逐月发放 | H6: 提前续购按R-07衔接；年路径仅在年购开放后启用 | I6: MKT-G02～G04 | J6: 规则适用已开放SKU；4档按实际额度比较，不使用旧1x/5x/10x
A7: 三类结算总则 | B7: A同周期即时；B纯月升年到期；C混合月升年即时 | C7: A保留周期；B原月到期起年；C当日起完整年 | D7: A按差价×剩余比例；B完整年费；C基础来源全额年费，专业来源年费减软件剩余价值 | E7: 积分不折现抵扣；充值余额及到期日不变 | F7: A按当前积分月补差；B无补发；C发新首月完整额度 | G7: A保留原锚点；B年周期开始建立锚点；C升级日建立锚点 | H7: 首月及次期口径见R-07；原订单已承诺权益按R-06处理 | I7: R-16～18；PM-03、MKT-G01～04 | J7: 业务规则已确认；计时精度、价格拆分与舍入待落地
A8: 三类积分处理 | B8: 按对应升级类型生效 | C8: 仅C类旧订阅积分到期调整为新首个积分月末 | D8: 旧订阅积分保留、不折现；不重复计入现金抵扣 | E8: A原批次原到期日；B当前月照常到期；C余额保留至新首月末 | F8: A差额×当前积分月剩余比例；B无；C完整目标首月额度 | G8: 年购每月发放，不一次发全年；充值积分原有效期不变 | H8: C类并非旧到期日再加1个月，也非顺延1年 | I8: R-18；MKT-G01～03 | J8: 2026-09-11确认
A9: 降级 / 取消 | B9: 当前周期不即时降级 | C9: 周期结束后重新选择 | D9: 不按降级规则自动退款；退款按R-20 | E9: 当前订阅积分按原/延长后的到期日使用 | F9: 不补发 | G9: 重新购买后按新档发放 | H9: 预约降级首期不做，后续再决策 | I9: MKT-G04、BKL-01 | J9: 首期范围已确认
A10: 首次购买首月优惠 | B10: 仅首次购买符合资格的首期 | C10: 每次续 1 个月 | D10: 首月用优惠价；次期按购买前明确展示的正常月价 | E10: 按订阅档位发放 | F10: 不因续费额外赠送 | G10: 每月正常发放 | H10: 首月金额引用最新源；优惠资格待确认 | I10: MKT-P18、REL-04 | J10: 会议46:14–46:40机制确认；配置待批准
A11: 正常月购 / 提前续购 | B11: 主动支付后预约衔接 | C11: 原周期结束后开始下一个月 | D11: 支付所选方案完整月费 | E11: 现有积分按原到期日处理 | F11: 新周期开始时发放 | G11: 按新周期发放 | H11: 单次购买，不自动续费 | I11: MKT-P18、REL-04 | J11: 沿最近灰度确认；本次周期范围待确认
A12: C 端年购 | B12: 新购立即；纯月升年在原月到期后生效；混合月升年立即 | C12: 从对应生效日开始完整1年；积分按月发放 | D12: 新购/纯月升年付完整年费；混合月升年按来源版本结算，见C类 | E12: 每批按月到期 | F12: 仅按活动规则发放 | G12: 每月发放，不一次性发全年 | H12: 不是订阅；到期按届时定价重新购买 | I12: MKT-P05、REL-04 | J12: 年购机制保留；本轮是否开放待确认
... A23: 待落地：计费细节与未生效年购订单 | B23: 具体实现待产品/财务确认 | C23: 计时精度、月末日期、舍入及已预约年周期变更待定义 | D23: 当前首次升级源价按当期实付；连续升级和专业软件实付拆分待定；倒推软件价值不直接作为折抵 | E23: 不得将含积分的整单余额抵扣后再完整结转积分 | F23: 赠送/付费积分拆分及取整实现需校验 | G23: 已付纯月升年尚未生效时再升级，需先处理原年购订单 | H23: 不得因再次升级重复收取整笔年费 | I23: PM-03；R-17～18 | J23: 阻塞真实订单结算；抽象比例用例可先开发

Sheet 复查与开发交付
A1: 编号/类型 | B1: 主题 | C1: 结论 / 开发约束 | D1: 状态 | E1: 来源 / 位置 | F1: 归口 | G1: 备注
A2: 版本 | B2: D5-PRICING-SYNC-20260918 | C2: 最新成果作为唯一来源，其他表与To Do、母版同步 | D2: 本轮复核 | E2: 快照基线rev726 | F2: 市场/产品 | G2: 不修改定价推演（最终）和AI权益
A3: 源01 | B3: 价格 | C3: 四档；CNY价与调优价并存；页显采用列待确认 | D3: 成果已确认 | E3: 定价推演 （最终） | F3: 市场/产品 | G3: 不按旧2000+1000结构推导
A4: 源02 | B4: AI权益 | C4: 并发、分辨率、模型、商用、充值、增强/放大与未上线协作 | D4: 成果已确认 | E4: AI 权益 | F4: 产品 | G4: 空白分享链接不补猜
A5: 同步01 | B5: C端完整定价 | C5: 重建为公式引用视图；清理独立旧价格与参数 | D5: 本轮更新 | E5: C端完整定价 | F5: 市场 | G5: 历史订单不追溯
A6: 同步02 | B6: 首发与年付口径 | C6: 区分首月/月/年和两列价格；不强制8折 | D6: 本轮更新 | E6: 首发与年付口径 | F6: 市场 | G6: 年价存在不等于已上架
A7: 同步03 | B7: 充值与毛利 | C7: 充值按档位权益，20汇率仅候选；模型成本仅假设 | D7: 本轮更新 | E7: 充值包；成本与毛利 | F7: 产品/财务 | G7: 不把未定方案当生产
A8: 同步04 | B8: 用例引用 | C8: 修复已删除灰度源导致的REF；新用例使用最终源 | D8: 已修复；16个新方案算术用例通过 | E8: 新方案验收用例 | F8: 测试 | G8: 旧算法夹具明确历史边界
A9: P01 | B9: 实际开放范围 | C9: 四档开放范围、月购/年购、上架时间与人群需确认 | D9: 待确认 | E9: R-04/R-22 | F9: 产品/市场 | G9: 未确认保持此前灰度单次月购约束
A10: P02 | B10: 页面采用价格列 | C10: CNY价与调优价同时保存，需锁定页面/订单采用列 | D10: 待确认 | E10: R-02 | F10: 市场/产品 | G10: 不改最新源
A11: P03 | B11: 充值及开业活动 | C11: 最终充值汇率/门槛、总赠送或额外叠加、活动起止与资格 | D11: 待确认 | E11: R-06/R-13/R-14 | F11: 市场/产品 | G11: 最新常态比例与期限已知
A12: P04 | B12: 升级订单计费 | C12: 首次用当期实付；连续升级基准、时间与金额舍入、软件实付拆分需验收 | D12: 待联调/确认 | E12: R-17/R-18 | F12: 产品/财务 | G12: 倒推软件价差不直接作折抵
... A20: 验收03 | B20: 页面同步范围 | C20: To Do与母版已更新；白板、Demo、公开网页及真实页面需另行校准。 | D20: 资料已同步；页面待验收 | E20: MKT-GRAY-07/08 | F20: 市场/产品 | G20: 未发布或发送通知

Sheet 计费验收用例
A1: 用例ID | B1: 场景 | C1: 算法类 | D1: 原周期价P0 | E1: 目标周期价P1 | F1: 剩余计费比例r | G1: 剩余积分月比例m | H1: 软件实付S0 | I1: 原月额度Q0 | J1: 目标月额度Q1 | K1: 旧订阅余额 | L1: 应付计算 | M1: 独立预期应付 | N1: 本次发分计算 | O1: 独立预期发分 | P1: 核对结果 | Q1: 周期断言 | R1: 旧积分断言 | S1: 范围 / 边界 | T1: 依据
A2: A01 | B2: 基础月1x→5x | C2: A | D2: 100 | E2: 500 | F2: 0.5 | G2: 0.5 | H2: 0 | I2: 2000 | J2: 10000 | K2: 500 | L2: =IF(C2="A",(E2-D2)*F2,IF(C2="C_PRO",E2-H2*F2,E2)) | M2: 200 | N2: =IF(C2="A",(J2-I2)*G2,IF(C2="B",0,J2)) | O2: 4000 | P2: =IF(AND(ABS(L2-M2)<1E-8,ABS(N2-O2)<1E-8),"通过","失败") | Q2: 原到期日和积分月锚点不变 | R2: 旧积分原到期日不变 | S2: 历史方案数值夹具；不用于新方案售价/可售判定；新用例见新方案验收用例 | T2: S01/S02；R-17/R-18
A3: A02 | B3: 专业月0x→1x | C3: A | D3: 200 | E3: 300 | F3: 0.5 | G3: 0.5 | H3: 200 | I3: 1000 | J3: 3000 | K3: 500 | L3: =IF(C3="A",(E3-D3)*F3,IF(C3="C_PRO",E3-H3*F3,E3)) | M3: 50 | N3: =IF(C3="A",(J3-I3)*G3,IF(C3="B",0,J3)) | O3: 1000 | P3: =IF(AND(ABS(L3-M3)<1E-8,ABS(N3-O3)<1E-8),"通过","失败") | Q3: 原到期日和积分月锚点不变 | R3: 旧积分原到期日不变 | S3: 历史方案数值夹具；不用于新方案售价/可售判定；新用例见新方案验收用例 | T3: S01/S02；R-17/R-18
A4: A03 | B4: 基础月→专业月同档 | C4: A | D4: 100 | E4: 300 | F4: 0.5 | G4: 0.5 | H4: 0 | I4: 2000 | J4: 3000 | K4: 500 | L4: =IF(C4="A",(E4-D4)*F4,IF(C4="C_PRO",E4-H4*F4,E4)) | M4: 100 | N4: =IF(C4="A",(J4-I4)*G4,IF(C4="B",0,J4)) | O4: 500 | P4: =IF(AND(ABS(L4-M4)<1E-8,ABS(N4-O4)<1E-8),"通过","失败") | Q4: 原到期日和积分月锚点不变 | R4: 旧积分原到期日不变 | S4: 历史方案数值夹具；不用于新方案售价/可售判定；新用例见新方案验收用例 | T4: S01/S02；R-17/R-18
A5: A04 | B5: 基础年1x→5x | C5: A | D5: 960 | E5: 4800 | F5: 0.25 | G5: 0.5 | H5: 0 | I5: 2000 | J5: 10000 | K5: 500 | L5: =IF(C5="A",(E5-D5)*F5,IF(C5="C_PRO",E5-H5*F5,E5)) | M5: 960 | N5: =IF(C5="A",(J5-I5)*G5,IF(C5="B",0,J5)) | O5: 4000 | P5: =IF(AND(ABS(L5-M5)<1E-8,ABS(N5-O5)<1E-8),"通过","失败") | Q5: 原到期日和积分月锚点不变 | R5: 旧积分原到期日不变 | S5: 历史方案数值夹具；不用于新方案售价/可售判定；新用例见新方案验收用例 | T5: S01/S02；R-17/R-18
A6: A05 | B6: 专业年0x→1x | C6: A | D6: 1920 | E6: 2880 | F6: 0.25 | G6: 0.5 | H6: 0 | I6: 1000 | J6: 3000 | K6: 500 | L6: =IF(C6="A",(E6-D6)*F6,IF(C6="C_PRO",E6-H6*F6,E6)) | M6: 240 | N6: =IF(C6="A",(J6-I6)*G6,IF(C6="B",0,J6)) | O6: 1000 | P6: =IF(AND(ABS(L6-M6)<1E-8,ABS(N6-O6)<1E-8),"通过","失败") | Q6: 原到期日和积分月锚点不变 | R6: 旧积分原到期日不变 | S6: 历史方案数值夹具；不用于新方案售价/可售判定；新用例见新方案验收用例 | T6: S01/S02；R-17/R-18
A7: A06 | B7: 基础年→专业年同档 | C7: A | D7: 960 | E7: 2880 | F7: 0.25 | G7: 0.5 | H7: 0 | I7: 2000 | J7: 3000 | K7: 500 | L7: =IF(C7="A",(E7-D7)*F7,IF(C7="C_PRO",E7-H7*F7,E7)) | M7: 480 | N7: =IF(C7="A",(J7-I7)*G7,IF(C7="B",0,J7)) | O7: 500 | P7: =IF(AND(ABS(L7-M7)<1E-8,ABS(N7-O7)<1E-8),"通过","失败") | Q7: 原到期日和积分月锚点不变 | R7: 旧积分原到期日不变 | S7: 历史方案数值夹具；不用于新方案售价/可售判定；新用例见新方案验收用例 | T7: S01/S02；R-17/R-18
A8: B01 | B8: 基础同版本同额度月→年 | C8: B | D8: 100 | E8: 960 | F8: 0.5 | G8: 0.5 | H8: 0 | I8: 2000 | J8: 2000 | K8: 500 | L8: =IF(C8="A",(E8-D8)*F8,IF(C8="C_PRO",E8-H8*F8,E8)) | M8: 960 | N8: =IF(C8="A",(J8-I8)*G8,IF(C8="B",0,J8)) | O8: 0 | P8: =IF(AND(ABS(L8-M8)<1E-8,ABS(N8-O8)<1E-8),"通过","失败") | Q8: 原月到期后开启完整年 | R8: 旧积分原到期日不变 | S8: 历史方案数值夹具；不用于新方案售价/可售判定；新用例见新方案验收用例 | T8: S01/S02；R-17/R-18
A9: B02 | B9: 专业同版本同额度月→年 | C9: B | D9: 200 | E9: 1920 | F9: 0.5 | G9: 0.5 | H9: 200 | I9: 1000 | J9: 1000 | K9: 500 | L9: =IF(C9="A",(E9-D9)*F9,IF(C9="C_PRO",E9-H9*F9,E9)) | M9: 1920 | N9: =IF(C9="A",(J9-I9)*G9,IF(C9="B",0,J9)) | O9: 0 | P9: =IF(AND(ABS(L9-M9)<1E-8,ABS(N9-O9)<1E-8),"通过","失败") | Q9: 原月到期后开启完整年 | R9: 旧积分原到期日不变 | S9: 历史方案数值夹具；不用于新方案售价/可售判定；新用例见新方案验收用例 | T9: S01/S02；R-17/R-18
A10: C01 | B10: 基础月1x→基础年5x | C10: C_BASIC | D10: 100 | E10: 4800 | F10: 0.5 | G10: 0.5 | H10: 0 | I10: 2000 | J10: 10000 | K10: 500 | L10: =IF(C10="A",(E10-D10)*F10,IF(C10="C_PRO",E10-H10*F10,E10)) | M10: 4800 | N10: =IF(C10="A",(J10-I10)*G10,IF(C10="B",0,J10)) | O10: 10000 | P10: =IF(AND(ABS(L10-M10)<1E-8,ABS(N10-O10)<1E-8),"通过","失败") | Q10: 升级日开启完整年与新积分月 | R10: 旧余额500保留至新首个积分月末；充值不变 | S10: 历史方案数值夹具；不用于新方案售价/可售判定；新用例见新方案验收用例 | T10: S01/S02；R-17/R-18
A11: C02 | B11: 专业月0x→专业年1x | C11: C_PRO | D11: 200 | E11: 2880 | F11: 0.5 | G11: 0.5 | H11: 200 | I11: 1000 | J11: 3000 | K11: 500 | L11: =IF(C11="A",(E11-D11)*F11,IF(C11="C_PRO",E11-H11*F11,E11)) | M11: 2780 | N11: =IF(C11="A",(J11-I11)*G11,IF(C11="B",0,J11)) | O11: 3000 | P11: =IF(AND(ABS(L11-M11)<1E-8,ABS(N11-O11)<1E-8),"通过","失败") | Q11: 升级日开启完整年与新积分月 | R11: 旧余额500保留至新首个积分月末；充值不变 | S11: 历史方案数值夹具；不用于新方案售价/可售判定；新用例见新方案验收用例 | T11: S01/S02；R-17/R-18
A12: C03 | B12: 基础月→专业年 | C12: C_BASIC | D12: 100 | E12: 2880 | F12: 0.5 | G12: 0.5 | H12: 0 | I12: 2000 | J12: 3000 | K12: 500 | L12: =IF(C12="A",(E12-D12)*F12,IF(C12="C_PRO",E12-H12*F12,E12)) | M12: 2880 | N12: =IF(C12="A",(J12-I12)*G12,IF(C12="B",0,J12)) | O12: 3000 | P12: =IF(AND(ABS(L12-M12)<1E-8,ABS(N12-O12)<1E-8),"通过","失败") | Q12: 升级日开启完整年与新积分月 | R12: 旧余额500保留至新首个积分月末；充值不变 | S12: 历史方案数值夹具；不用于新方案售价/可售判定；新用例见新方案验收用例 | T12: S01/S02；R-17/R-18
A13: A07 | B13: 重复升级：当前基础5x→10x | C13: A | D13: 500 | E13: 1000 | F13: 0.25 | G13: 0.25 | H13: 0 | I13: 10000 | J13: 20000 | K13: 0 | L13: =IF(C13="A",(E13-D13)*F13,IF(C13="C_PRO",E13-H13*F13,E13)) | M13: 125 | N13: =IF(C13="A",(J13-I13)*G13,IF(C13="B",0,J13)) | O13: 2500 | P13: =IF(AND(ABS(L13-M13)<1E-8,ABS(N13-O13)<1E-8),"通过","失败") | Q13: 原到期日和积分月锚点不变 | R13: 旧积分原到期日不变 | S13: 历史方案数值夹具；不用于新方案售价/可售判定；新用例见新方案验收用例 | T13: S01/S02；R-17/R-18
... A19: A11 | B19: 年剩余1/2、积分月剩余1/4 | C19: A | D19: 960 | E19: 2880 | F19: 0.5 | G19: 0.25 | H19: 0 | I19: 2000 | J19: 3000 | K19: 500 | L19: =IF(C19="A",(E19-D19)*F19,IF(C19="C_PRO",E19-H19*F19,E19)) | M19: 960 | N19: =IF(C19="A",(J19-I19)*G19,IF(C19="B",0,J19)) | O19: 250 | P19: =IF(AND(ABS(L19-M19)<1E-8,ABS(N19-O19)<1E-8),"通过","失败") | Q19: 原到期日和积分月锚点不变 | R19: 旧积分原到期日不变 | S19: 历史方案数值夹具；不用于新方案售价/可售判定；新用例见新方案验收用例 | T19: S01/S02；R-17/R-18
A21: 测试说明 | B21: 旧方案算法夹具归档：D:O数值只用于历史算法回归，不是最新价格。新方案请看新方案验收用例。下方改为最新充值权益校验，不测未确认汇率与活动叠加。
A23: ID | B23: 版本档位 | C23: 权益源行 | D23: 常态赠送原文 | E23: 独立预期 | F23: 有效期原文 | G23: 独立预期 | H23: 并发源 | I23: 独立预期 | J23: 视频规格源 | K23: 独立预期 | L23: 核对 | M23: 活动原文 | N23: 活动使用边界 | O23: 来源 | P23: 验收层级
A24: R01 | B24: 基础版 入门 | C24: 3 | D24: ='AI 权益'!$G$3 | E24: 标准价格 | F24: ='AI 权益'!$H$3 | G24: 90天 | H24: ='AI 权益'!$B$3 | I24: 4 | J24: ='AI 权益'!$D$3 | K24: 720 P | L24: =IF(AND($D$24=$E$24,$F$24=$G$24,$H$24=$I$24,$J$24=$K$24),"通过","失败") | M24: ='AI 权益'!$N$3 | N24: 叠加与日期待确认 | O24: AI 权益 | P24: 仅表格权益一致性，非支付验收
A25: R02 | B25: 基础版 轻量 | C25: 4 | D25: ='AI 权益'!$G$4 | E25: 标准价格 | F25: ='AI 权益'!$H$4 | G25: 90天 | H25: ='AI 权益'!$B$4 | I25: 6 | J25: ='AI 权益'!$D$4 | K25: 4K | L25: =IF(AND($D$25=$E$25,$F$25=$G$25,$H$25=$I$25,$J$25=$K$25),"通过","失败") | M25: ='AI 权益'!$N$4 | N25: 叠加与日期待确认 | O25: AI 权益 | P25: 仅表格权益一致性，非支付验收
A26: R03 | B26: 基础版 标准 | C26: 5 | D26: ='AI 权益'!$G$5 | E26: 额外赠送10% | F26: ='AI 权益'!$H$5 | G26: 90天 | H26: ='AI 权益'!$B$5 | I26: 10 | J26: ='AI 权益'!$D$5 | K26: 4K | L26: =IF(AND($D$26=$E$26,$F$26=$G$26,$H$26=$I$26,$J$26=$K$26),"通过","失败") | M26: ='AI 权益'!$N$5 | N26: 叠加与日期待确认 | O26: AI 权益 | P26: 仅表格权益一致性，非支付验收
A27: R04 | B27: 基础版 旗舰 | C27: 6 | D27: ='AI 权益'!$G$6 | E27: 额外赠送10% | F27: ='AI 权益'!$H$6 | G27: 90天 | H27: ='AI 权益'!$B$6 | I27: 不限 | J27: ='AI 权益'!$D$6 | K27: 4K | L27: =IF(AND($D$27=$E$27,$F$27=$G$27,$H$27=$I$27,$J$27=$K$27),"通过","失败") | M27: ='AI 权益'!$N$6 | N27: 叠加与日期待确认 | O27: AI 权益 | P27: 仅表格权益一致性，非支付验收
A28: R05 | B28: 专业版 入门 | C28: 7 | D28: ='AI 权益'!$G$7 | E28: 额外赠送10% | F28: ='AI 权益'!$H$7 | G28: 180天 | H28: ='AI 权益'!$B$7 | I28: 4 | J28: ='AI 权益'!$D$7 | K28: 4K | L28: =IF(AND($D$28=$E$28,$F$28=$G$28,$H$28=$I$28,$J$28=$K$28),"通过","失败") | M28: ='AI 权益'!$N$7 | N28: 叠加与日期待确认 | O28: AI 权益 | P28: 仅表格权益一致性，非支付验收
A29: R06 | B29: 专业版 轻量 | C29: 8 | D29: ='AI 权益'!$G$8 | E29: 额外赠送10% | F29: ='AI 权益'!$H$8 | G29: 180天 | H29: ='AI 权益'!$B$8 | I29: 6 | J29: ='AI 权益'!$D$8 | K29: 4K | L29: =IF(AND($D$29=$E$29,$F$29=$G$29,$H$29=$I$29,$J$29=$K$29),"通过","失败") | M29: ='AI 权益'!$N$8 | N29: 叠加与日期待确认 | O29: AI 权益 | P29: 仅表格权益一致性，非支付验收
A30: R07 | B30: 专业版 标准 | C30: 9 | D30: ='AI 权益'!$G$9 | E30: 额外赠送20% | F30: ='AI 权益'!$H$9 | G30: 180天 | H30: ='AI 权益'!$B$9 | I30: 10 | J30: ='AI 权益'!$D$9 | K30: 4K | L30: =IF(AND($D$30=$E$30,$F$30=$G$30,$H$30=$I$30,$J$30=$K$30),"通过","失败") | M30: ='AI 权益'!$N$9 | N30: 叠加与日期待确认 | O30: AI 权益 | P30: 仅表格权益一致性，非支付验收
A31: R08 | B31: 专业版 旗舰 | C31: 10 | D31: ='AI 权益'!$G$10 | E31: 额外赠送20% | F31: ='AI 权益'!$H$10 | G31: 180天 | H31: ='AI 权益'!$B$10 | I31: 不限 | J31: ='AI 权益'!$D$10 | K31: 4K | L31: =IF(AND($D$31=$E$31,$F$31=$G$31,$H$31=$I$31,$J$31=$K$31),"通过","失败") | M31: ='AI 权益'!$N$10 | N31: 叠加与日期待确认 | O31: AI 权益 | P31: 仅表格权益一致性，非支付验收
A32: R09 | B32: 社区不可充值 | C32: 2 | D32: ='AI 权益'!$G$2 | E32: 不可充值 | L32: =IF($D$32=$E$32,"通过","失败") | O32: AI 权益 | P32: 资格实现待验收
A33: 边界 | B33: 新汇率20为候选；充值报价未确定，移除旧30及500/5000金额阶梯算术，避免生成虚假的通过结果。

Sheet 新方案补充与开发说明
A1: 规则ID | B1: 资料主题 | C1: 补充规则 / 开发要求 | D1: 确认状态 | E1: 依据 | F1: 尚需补充 / 验收边界 | G1: 责任归口（建议）
A2: G-01 | B2: 价格/权益来源 | C2: 价格数值只引用「定价推演 （最终）」；「C端完整定价」为引用展示，不再维护独立价格。C列价格与D列调优价格分别保留；页面最终采用哪列待确认。 | D2: 源表已确认；展示列待确认 | E2: R-02；定价推演（最终）/AI权益 | F2: 2026-09-18用户指定最新成果；本轮源表不修改。 | G2: 按原任务归口推进
A3: G-02 | B3: 可售配置 | C3: 四档价格和AI权益已形成最新成果；实际开放档位、月购/年购、人群、时间、SKU与回滚需确认。价格确定不等于可售与上线完成。 | D3: 待发布配置确认 | E3: R-22；定价推演（最终）/AI权益 | F3: 此前仅单次月购口径在新决定前保留；不给缺失事项补结论。 | G3: 按原任务归口推进
A4: G-03 | B4: 同档积分齐平 | C4: 同档基础版与专业版总积分齐平：1000/2700/6000/13000每月。年行12000/32400/72000/156000为年度总额，不是每月额度；后台付费/赠送拆分另确认。 | D4: 总额度已确认 | E4: R-09；定价推演（最终）/AI权益 | F4: 不得额外给专业版叠加1000积分；前台不宣传未经确认的拆分。 | G4: 按原任务归口推进
A5: G-04 | B5: 价格采用列 | C5: 价格数值只引用「定价推演 （最终）」；「C端完整定价」为引用展示，不再维护独立价格。C列价格与D列调优价格分别保留；页面最终采用哪列待确认。 | D5: 源表已确认；展示列待确认 | E5: R-02；定价推演（最终）/AI权益 | F5: 2026-09-18用户指定最新成果；本轮源表不修改。 | G5: 按原任务归口推进
A6: G-05 | B6: 价格展示 | C6: 每档区分常规月价、首月价、年价；旧标准/长期/首发三套价格停止作为新方案依据。首月价仅首期，不永久锁价。 | D6: 按最新价表更新 | E6: R-03；定价推演（最终）/AI权益 | F6: 年价是独立金额，不用统一八折或软件固定加价反推。 | G6: 按原任务归口推进
A7: G-06 | B7: 首购资格 | C7: 首月金额引用最新价表的首月行；正常月价引用月行。首购识别、旧用户资格、跨版本/周期共享及优惠活动叠加需产品确认。 | D7: 金额源已确认；资格待确认 | E7: R-05；定价推演（最终）/AI权益 | F7: 不沿用首发结束后才启用首购、首购年价600/2200等旧规则。 | G7: 按原任务归口推进
A8: G-07 | B8: 年购与月发 | C8: 最新表已给出年价，但不等于灰度开放年购；本轮开放周期待确认。此前灰度为单次月购、无自动续费；若开放年购，沿用单次购买、积分按月发放。 | D8: 开放范围待确认 | E8: R-04；定价推演（最终）/AI权益 | F8: 未确认前不自动新增年付或自动续费入口。 | G8: 按原任务归口推进
A9: G-08 | B9: A类升级 | C9: A同周期：价差×剩余计费比例，即时生效、到期日不变；首次升级以当期实付为源基准。B纯月升年：完整年费、原月到期衔接。C混合月升年：即时起完整年，基础来源全额，专业来源减软件实付剩余价值。 | D9: 机制沿用；年路径按开放范围启用 | E9: R-17；定价推演（最终）/AI权益 | F9: 倒推软件价值只是价差观察，不自动等于订单的软件实付拆分；连续升级、金额舍入待联调。 | G9: 按原任务归口推进
A10: G-09 | B10: 积分补发 | C10: A补发=向上取整[(目标月额度−当前月额度)×当前积分月剩余比例]，旧/补发积分原积分月末到期；同额度为0。B当前月不补发、不延期。C发目标首月完整额度，旧方案余额至新首月末，充值到期日不变。 | D10: 沿最近产品/母版规则同步 | E10: R-18；定价推演（最终）/AI权益 | F10: 年剩余计费比例与当月积分比例分开；不按未用积分折现金。 | G10: 按原任务归口推进
A11: G-10 | B11: B类纯月升年 | C11: 同周期可在已开放SKU中升版本或提额，目标额度不降低；同档基础→专业额度相同，不补积分。基础版和专业版同版本提额均适用。纯月升年仅同版本同额度；其他月升年为混合类。 | D11: 机制已确认；SKU路径待联调 | E11: R-16；定价推演（最终）/AI权益 | F11: 不同方案版本的老订单不自动迁移；基础高档→专业低档需单独决策。 | G11: 按原任务归口推进
A12: G-11 | B12: C类混合月升年 | C12: A同周期：价差×剩余计费比例，即时生效、到期日不变；首次升级以当期实付为源基准。B纯月升年：完整年费、原月到期衔接。C混合月升年：即时起完整年，基础来源全额，专业来源减软件实付剩余价值。 | D12: 机制沿用；年路径按开放范围启用 | E12: R-17；定价推演（最终）/AI权益 | F12: 倒推软件价值只是价差观察，不自动等于订单的软件实付拆分；连续升级、金额舍入待联调。 | G12: 按原任务归口推进
... A28: G-25 | B28: 成本与充值基准 | C28: 社区版不可充值；有效基础/专业会员可充值。50元起且50的倍数沿此前口径；新充值表为未确定版，20积分/元是候选，旧30积分/元停止作为已确认新方案宣传。 | D28: 汇率/门槛最终配置待确认 | E28: R-13；定价推演（最终）/AI权益 | F28: 不能同时使用20积分/元和金额×30；金额计算暂不作为生产报价。 | G28: 按原任务归口推进

Sheet 新方案验收用例
A1: ID | B1: 场景（调优价算术用例） | C1: 分类 | D1: 原周期价格 | E1: 目标周期价格 | F1: 剩余周期比例 | G1: 原月积分 | H1: 目标月积分 | I1: 旧余额（夹具） | J1: 应付计算 | K1: 独立预期应付 | L1: 本次新发积分 | M1: 独立预期新发 | N1: 检查 | O1: 周期断言 | P1: 使用边界
A2: N01 | B2: 基础入门月→专业入门月 | C2: A | D2: ='定价推演 （最终）'!$D$3 | E2: ='定价推演 （最终）'!$D$15 | F2: 0.5 | G2: 1000 | H2: 1000 | I2: 500 | J2: =($E$2-$D$2)*$F$2 | K2: 75.5 | L2: =ROUNDUP(($H$2-$G$2)*$F$2,0) | M2: 0 | N2: =IF(AND(ABS($J$2-$K$2)<0.000001,$L$2=$M$2),"通过","失败") | O2: A不变；B原月到期衔接；C即时起新年；NEW按购买/续购生效时点 | P2: 按调优列作算术情景；不是上线选列决定；年购开放另确认
A3: N02 | B3: 基础入门年→专业入门年 | C3: A | D3: ='定价推演 （最终）'!$D$5 | E3: ='定价推演 （最终）'!$D$17 | F3: 0.5 | G3: 1000 | H3: 1000 | I3: 500 | J3: =($E$3-$D$3)*$F$3 | K3: 760.5 | L3: =ROUNDUP(($H$3-$G$3)*$F$3,0) | M3: 0 | N3: =IF(AND(ABS($J$3-$K$3)<0.000001,$L$3=$M$3),"通过","失败") | O3: A不变；B原月到期衔接；C即时起新年；NEW按购买/续购生效时点 | P3: 按调优列作算术情景；不是上线选列决定；年购开放另确认
A4: N03 | B4: 基础入门纯月升年 | C4: B | D4: ='定价推演 （最终）'!$D$3 | E4: ='定价推演 （最终）'!$D$5 | F4: 0.5 | G4: 1000 | H4: 1000 | I4: 500 | J4: =$E$4 | K4: 399 | L4: 0 | M4: 0 | N4: =IF(AND(ABS($J$4-$K$4)<0.000001,$L$4=$M$4),"通过","失败") | O4: A不变；B原月到期衔接；C即时起新年；NEW按购买/续购生效时点 | P4: 按调优列作算术情景；不是上线选列决定；年购开放另确认
A5: N04 | B5: 专业入门纯月升年 | C5: B | D5: ='定价推演 （最终）'!$D$15 | E5: ='定价推演 （最终）'!$D$17 | F5: 0.5 | G5: 1000 | H5: 1000 | I5: 500 | J5: =$E$5 | K5: 1920 | L5: 0 | M5: 0 | N5: =IF(AND(ABS($J$5-$K$5)<0.000001,$L$5=$M$5),"通过","失败") | O5: A不变；B原月到期衔接；C即时起新年；NEW按购买/续购生效时点 | P5: 按调优列作算术情景；不是上线选列决定；年购开放另确认
A6: N05 | B6: 基础入门月→专业轻量年 | C6: C | D6: ='定价推演 （最终）'!$D$3 | E6: ='定价推演 （最终）'!$D$20 | F6: 0.5 | G6: 1000 | H6: 2700 | I6: 500 | J6: =$E$6 | K6: 2499 | L6: =$H$6 | M6: 2700 | N6: =IF(AND(ABS($J$6-$K$6)<0.000001,$L$6=$M$6),"通过","失败") | O6: A不变；B原月到期衔接；C即时起新年；NEW按购买/续购生效时点 | P6: 按调优列作算术情景；不是上线选列决定；年购开放另确认
A7: N06 | B7: 同档积分已用完 | C7: A | D7: ='定价推演 （最终）'!$D$3 | E7: ='定价推演 （最终）'!$D$15 | F7: 0.5 | G7: 1000 | H7: 1000 | I7: 0 | J7: =($E$7-$D$7)*$F$7 | K7: 75.5 | L7: =ROUNDUP(($H$7-$G$7)*$F$7,0) | M7: 0 | N7: =IF(AND(ABS($J$7-$K$7)<0.000001,$L$7=$M$7),"通过","失败") | O7: A不变；B原月到期衔接；C即时起新年；NEW按购买/续购生效时点 | P7: 按调优列作算术情景；不是上线选列决定；年购开放另确认
A8: N07 | B8: 混合升级旧余额为0 | C8: C | D8: ='定价推演 （最终）'!$D$3 | E8: ='定价推演 （最终）'!$D$20 | F8: 0.5 | G8: 1000 | H8: 2700 | I8: 0 | J8: =$E$8 | K8: 2499 | L8: =$H$8 | M8: 2700 | N8: =IF(AND(ABS($J$8-$K$8)<0.000001,$L$8=$M$8),"通过","失败") | O8: A不变；B原月到期衔接；C即时起新年；NEW按购买/续购生效时点 | P8: 按调优列作算术情景；不是上线选列决定；年购开放另确认
A9: N08 | B9: 基础入门→轻量比例1 | C9: A | D9: ='定价推演 （最终）'!$D$3 | E9: ='定价推演 （最终）'!$D$6 | F9: 1 | G9: 1000 | H9: 2700 | I9: 500 | J9: =($E$9-$D$9)*$F$9 | K9: 80 | L9: =ROUNDUP(($H$9-$G$9)*$F$9,0) | M9: 1700 | N9: =IF(AND(ABS($J$9-$K$9)<0.000001,$L$9=$M$9),"通过","失败") | O9: A不变；B原月到期衔接；C即时起新年；NEW按购买/续购生效时点 | P9: 按调优列作算术情景；不是上线选列决定；年购开放另确认
A10: N09 | B10: 同周期比例0边界 | C10: A | D10: ='定价推演 （最终）'!$D$3 | E10: ='定价推演 （最终）'!$D$6 | F10: 0 | G10: 1000 | H10: 2700 | I10: 0 | J10: =($E$10-$D$10)*$F$10 | K10: 0 | L10: =ROUNDUP(($H$10-$G$10)*$F$10,0) | M10: 0 | N10: =IF(AND(ABS($J$10-$K$10)<0.000001,$L$10=$M$10),"通过","失败") | O10: A不变；B原月到期衔接；C即时起新年；NEW按购买/续购生效时点 | P10: 按调优列作算术情景；不是上线选列决定；年购开放另确认
A11: N10 | B11: 首月实付39升级轻量 | C11: A | D11: ='定价推演 （最终）'!$D$4 | E11: ='定价推演 （最终）'!$D$6 | F11: 0.5 | G11: 1000 | H11: 2700 | I11: 500 | J11: =($E$11-$D$11)*$F$11 | K11: 45 | L11: =ROUNDUP(($H$11-$G$11)*$F$11,0) | M11: 850 | N11: =IF(AND(ABS($J$11-$K$11)<0.000001,$L$11=$M$11),"通过","失败") | O11: A不变；B原月到期衔接；C即时起新年；NEW按购买/续购生效时点 | P11: 按调优列作算术情景；不是上线选列决定；年购开放另确认
A12: N11 | B12: 首购基础入门 | C12: NEW | D12: 0 | E12: ='定价推演 （最终）'!$D$4 | F12: 1 | G12: 0 | H12: 1000 | I12: 500 | J12: =$E$12 | K12: 39 | L12: =$H$12 | M12: 1000 | N12: =IF(AND(ABS($J$12-$K$12)<0.000001,$L$12=$M$12),"通过","失败") | O12: A不变；B原月到期衔接；C即时起新年；NEW按购买/续购生效时点 | P12: 按调优列作算术情景；不是上线选列决定；年购开放另确认
A13: N12 | B13: 首购专业入门 | C13: NEW | D13: 0 | E13: ='定价推演 （最终）'!$D$16 | F13: 1 | G13: 0 | H13: 1000 | I13: 500 | J13: =$E$13 | K13: 189 | L13: =$H$13 | M13: 1000 | N13: =IF(AND(ABS($J$13-$K$13)<0.000001,$L$13=$M$13),"通过","失败") | O13: A不变；B原月到期衔接；C即时起新年；NEW按购买/续购生效时点 | P13: 按调优列作算术情景；不是上线选列决定；年购开放另确认
A14: N13 | B14: 新购基础轻量年 | C14: NEW | D14: 0 | E14: ='定价推演 （最终）'!$D$8 | F14: 1 | G14: 0 | H14: 2700 | I14: 500 | J14: =$E$14 | K14: 999 | L14: =$H$14 | M14: 2700 | N14: =IF(AND(ABS($J$14-$K$14)<0.000001,$L$14=$M$14),"通过","失败") | O14: A不变；B原月到期衔接；C即时起新年；NEW按购买/续购生效时点 | P14: 按调优列作算术情景；不是上线选列决定；年购开放另确认
A15: N14 | B15: 新购专业旗舰年 | C15: NEW | D15: 0 | E15: ='定价推演 （最终）'!$D$26 | F15: 1 | G15: 0 | H15: 13000 | I15: 500 | J15: =$E$15 | K15: 5499 | L15: =$H$15 | M15: 13000 | N15: =IF(AND(ABS($J$15-$K$15)<0.000001,$L$15=$M$15),"通过","失败") | O15: A不变；B原月到期衔接；C即时起新年；NEW按购买/续购生效时点 | P15: 按调优列作算术情景；不是上线选列决定；年购开放另确认
A16: N15 | B16: 基础标准正常月续购 | C16: NEW | D16: ='定价推演 （最终）'!$D$9 | E16: ='定价推演 （最终）'!$D$9 | F16: 1 | G16: 6000 | H16: 6000 | I16: 500 | J16: =$E$16 | K16: 269 | L16: =$H$16 | M16: 6000 | N16: =IF(AND(ABS($J$16-$K$16)<0.000001,$L$16=$M$16),"通过","失败") | O16: A不变；B原月到期衔接；C即时起新年；NEW按购买/续购生效时点 | P16: 按调优列作算术情景；不是上线选列决定；年购开放另确认
A17: N16 | B17: 专业旗舰正常月续购 | C17: NEW | D17: ='定价推演 （最终）'!$D$24 | E17: ='定价推演 （最终）'!$D$24 | F17: 1 | G17: 13000 | H17: 13000 | I17: 500 | J17: =$E$17 | K17: 719 | L17: =$H$17 | M17: 13000 | N17: =IF(AND(ABS($J$17-$K$17)<0.000001,$L$17=$M$17),"通过","失败") | O17: A不变；B原月到期衔接；C即时起新年；NEW按购买/续购生效时点 | P17: 按调优列作算术情景；不是上线选列决定；年购开放另确认
A19: 使用边界 | B19: 本表验证调优价格情景算术，不证明可售、支付或上线。年测试当前月积分比例在同档案例为0差额；高档年升级用独立积分月比例。
A21: 验收ID | B21: 业务边界 | C21: 预期行为 | D21: 状态
A22: M01 | B22: 同档基础→专业 | C22: 积分不额外叠加1000；同周期不补分 | D22: 待真实联调
A23: M02 | B23: 纯与混合月升年 | C23: 同版本同额度才B；升版本或提额为C | D23: 年购开放后联调
A24: M03 | B24: 旧方案迁移 | C24: 识别原订单价格/权益版本，不自动覆盖历史承诺 | D24: 迁移待确认
A25: M04 | B25: 四档SKU | C25: 按真实可售名单拒绝未开放SKU | D25: 开放范围待确认
A26: M05 | B26: 支付回调重试 | C26: 不重复扣款/发积分 | D26: 待联调
A27: M06 | B27: 软件价值拆分 | C27: 倒推价差不自动作为软件实付抵扣 | D27: 财务/产品待确认
A28: M07 | B28: 月末/闰年 | C28: 统一锚点与舍入，不固定30天 | D28: 待联调
A29: M08 | B29: 开业活动 | C29: 常态与活动分开，不自动叠加 | D29: 口径待确认
A31: 展示ID | B31: 项目 | C31: 自动引用结果 | D31: 独立预期
A32: D01 | B32: 基础入门年购月均 | C32: ='定价推演 （最终）'!$D$5/12 | D32: 33.25
A33: D02 | B33: 基础入门年购较12次正常月购节省 | C33: ='定价推演 （最终）'!$D$3*12-'定价推演 （最终）'!$D$5 | D33: 189
A34: D03 | B34: 基础入门首月优惠加11次正常月购 | C34: ='定价推演 （最终）'!$D$4+'定价推演 （最终）'!$D$3*11 | D34: 578
A35: D04 | B35: 基础入门年购较优惠首年节省 | C35: ='定价推演 （最终）'!$D$4+'定价推演 （最终）'!$D$3*11-'定价推演 （最终）'!$D$5 | D35: 179
A36: D05 | B36: 专业入门年购月均 | C36: ='定价推演 （最终）'!$D$17/12 | D36: 160
A37: D06 | B37: 专业入门年购较正常全年节省 | C37: ='定价推演 （最终）'!$D$15*12-'定价推演 （最终）'!$D$17 | D37: 480

Sheet 月价呈现定价
A1: 基础版｜月价呈现定价 | O1: 专业版｜同档积分齐平
A2: 档位 | B2: 计费 | C2: 价格(CNY) | D2: 价格(USD) | E2: 月均积分 | F2: 单积分(USD) | G2: 较充值基准节省 | H2: 全年金额(CNY) | I2: 年购较常规月购省 | J2: 单位积分价较上一档省 | K2: 均值积分（积分/元） | L2: 每千积分(CNY) | M2: 年度总积分 | O2: 档位 | P2: 计费 | Q2: 价格(CNY) | R2: 价格(USD) | S2: 月均积分 | T2: 单积分(USD) | U2: 较充值基准节省 | V2: 全年金额(CNY) | W2: 年购较常规月购省 | X2: 单位积分价较上一档省 | Y2: 均值积分（积分/元） | Z2: 每千积分(CNY) | AA2: 年度总积分 | AB2: 同档专业能力价差
A3: =$A$24 | B3: 月 | C3: =$C$24 | D3: =$C$3/$M$23 | E3: =$B$24 | F3: =$D$3/$E$3 | G3: =1-$C$3/$E$3*$M$24 | H3: =$C$3*12 | K3: =$E$3/$C$3 | L3: =$C$3/$E$3*1000 | O3: =$A$24 | P3: 月 | Q3: =$C$24+$F$24 | R3: =$Q$3/$M$23 | S3: =$B$24 | T3: =$R$3/$S$3 | U3: =1-$Q$3/$S$3*$M$24 | V3: =$Q$3*12 | Y3: =$S$3/$Q$3 | Z3: =$Q$3/$S$3*1000 | AB3: =$Q$3-$C$3
A4: =$A$24 | B4: 首月 | C4: =$D$24 | D4: =$C$4/$M$23 | E4: =$B$24 | F4: =$D$4/$E$4 | G4: =1-$C$4/$E$4*$M$24 | K4: =$E$4/$C$4 | L4: =$C$4/$E$4*1000 | O4: =$A$24 | P4: 首月 | Q4: =$D$24+$G$24 | R4: =$Q$4/$M$23 | S4: =$B$24 | T4: =$R$4/$S$4 | U4: =1-$Q$4/$S$4*$M$24 | Y4: =$S$4/$Q$4 | Z4: =$Q$4/$S$4*1000 | AB4: =$Q$4-$C$4
A5: =$A$24 | B5: 年（折合月价） | C5: =$E$24 | D5: =$C$5/$M$23 | E5: =$B$24 | F5: =$D$5/$E$5 | G5: =1-$C$5/$E$5*$M$24 | H5: =$C$5*12 | I5: =1-$C$5/$C$3 | K5: =$E$5/$C$5 | L5: =$C$5/$E$5*1000 | M5: =$E$5*12 | O5: =$A$24 | P5: 年（折合月价） | Q5: =$E$24+$H$24 | R5: =$Q$5/$M$23 | S5: =$B$24 | T5: =$R$5/$S$5 | U5: =1-$Q$5/$S$5*$M$24 | V5: =$Q$5*12 | W5: =1-$Q$5/$Q$3 | Y5: =$S$5/$Q$5 | Z5: =$Q$5/$S$5*1000 | AA5: =$S$5*12 | AB5: =$Q$5-$C$5
A6: =$A$25 | B6: 月 | C6: =$C$25 | D6: =$C$6/$M$23 | E6: =$B$25 | F6: =$D$6/$E$6 | G6: =1-$C$6/$E$6*$M$24 | H6: =$C$6*12 | J6: =1-($C$6/$E$6)/($C$3/$E$3) | K6: =$E$6/$C$6 | L6: =$C$6/$E$6*1000 | O6: =$A$25 | P6: 月 | Q6: =$C$25+$F$25 | R6: =$Q$6/$M$23 | S6: =$B$25 | T6: =$R$6/$S$6 | U6: =1-$Q$6/$S$6*$M$24 | V6: =$Q$6*12 | X6: =1-($Q$6/$S$6)/($Q$3/$S$3) | Y6: =$S$6/$Q$6 | Z6: =$Q$6/$S$6*1000 | AB6: =$Q$6-$C$6
A7: =$A$25 | B7: 首月 | C7: =$D$25 | D7: =$C$7/$M$23 | E7: =$B$25 | F7: =$D$7/$E$7 | G7: =1-$C$7/$E$7*$M$24 | J7: =1-($C$7/$E$7)/($C$4/$E$4) | K7: =$E$7/$C$7 | L7: =$C$7/$E$7*1000 | O7: =$A$25 | P7: 首月 | Q7: =$D$25+$G$25 | R7: =$Q$7/$M$23 | S7: =$B$25 | T7: =$R$7/$S$7 | U7: =1-$Q$7/$S$7*$M$24 | X7: =1-($Q$7/$S$7)/($Q$4/$S$4) | Y7: =$S$7/$Q$7 | Z7: =$Q$7/$S$7*1000 | AB7: =$Q$7-$C$7
A8: =$A$25 | B8: 年（折合月价） | C8: =$E$25 | D8: =$C$8/$M$23 | E8: =$B$25 | F8: =$D$8/$E$8 | G8: =1-$C$8/$E$8*$M$24 | H8: =$C$8*12 | I8: =1-$C$8/$C$6 | J8: =1-($C$8/$E$8)/($C$5/$E$5) | K8: =$E$8/$C$8 | L8: =$C$8/$E$8*1000 | M8: =$E$8*12 | O8: =$A$25 | P8: 年（折合月价） | Q8: =$E$25+$H$25 | R8: =$Q$8/$M$23 | S8: =$B$25 | T8: =$R$8/$S$8 | U8: =1-$Q$8/$S$8*$M$24 | V8: =$Q$8*12 | W8: =1-$Q$8/$Q$6 | X8: =1-($Q$8/$S$8)/($Q$5/$S$5) | Y8: =$S$8/$Q$8 | Z8: =$Q$8/$S$8*1000 | AA8: =$S$8*12 | AB8: =$Q$8-$C$8
A9: =$A$26 | B9: 月 | C9: =$C$26 | D9: =$C$9/$M$23 | E9: =$B$26 | F9: =$D$9/$E$9 | G9: =1-$C$9/$E$9*$M$24 | H9: =$C$9*12 | J9: =1-($C$9/$E$9)/($C$6/$E$6) | K9: =$E$9/$C$9 | L9: =$C$9/$E$9*1000 | O9: =$A$26 | P9: 月 | Q9: =$C$26+$F$26 | R9: =$Q$9/$M$23 | S9: =$B$26 | T9: =$R$9/$S$9 | U9: =1-$Q$9/$S$9*$M$24 | V9: =$Q$9*12 | X9: =1-($Q$9/$S$9)/($Q$6/$S$6) | Y9: =$S$9/$Q$9 | Z9: =$Q$9/$S$9*1000 | AB9: =$Q$9-$C$9
A10: =$A$26 | B10: 首月 | C10: =$D$26 | D10: =$C$10/$M$23 | E10: =$B$26 | F10: =$D$10/$E$10 | G10: =1-$C$10/$E$10*$M$24 | J10: =1-($C$10/$E$10)/($C$7/$E$7) | K10: =$E$10/$C$10 | L10: =$C$10/$E$10*1000 | O10: =$A$26 | P10: 首月 | Q10: =$D$26+$G$26 | R10: =$Q$10/$M$23 | S10: =$B$26 | T10: =$R$10/$S$10 | U10: =1-$Q$10/$S$10*$M$24 | X10: =1-($Q$10/$S$10)/($Q$7/$S$7) | Y10: =$S$10/$Q$10 | Z10: =$Q$10/$S$10*1000 | AB10: =$Q$10-$C$10
A11: =$A$26 | B11: 年（折合月价） | C11: =$E$26 | D11: =$C$11/$M$23 | E11: =$B$26 | F11: =$D$11/$E$11 | G11: =1-$C$11/$E$11*$M$24 | H11: =$C$11*12 | I11: =1-$C$11/$C$9 | J11: =1-($C$11/$E$11)/($C$8/$E$8) | K11: =$E$11/$C$11 | L11: =$C$11/$E$11*1000 | M11: =$E$11*12 | O11: =$A$26 | P11: 年（折合月价） | Q11: =$E$26+$H$26 | R11: =$Q$11/$M$23 | S11: =$B$26 | T11: =$R$11/$S$11 | U11: =1-$Q$11/$S$11*$M$24 | V11: =$Q$11*12 | W11: =1-$Q$11/$Q$9 | X11: =1-($Q$11/$S$11)/($Q$8/$S$8) | Y11: =$S$11/$Q$11 | Z11: =$Q$11/$S$11*1000 | AA11: =$S$11*12 | AB11: =$Q$11-$C$11
A12: =$A$27 | B12: 月 | C12: =$C$27 | D12: =$C$12/$M$23 | E12: =$B$27 | F12: =$D$12/$E$12 | G12: =1-$C$12/$E$12*$M$24 | H12: =$C$12*12 | J12: =1-($C$12/$E$12)/($C$9/$E$9) | K12: =$E$12/$C$12 | L12: =$C$12/$E$12*1000 | O12: =$A$27 | P12: 月 | Q12: =$C$27+$F$27 | R12: =$Q$12/$M$23 | S12: =$B$27 | T12: =$R$12/$S$12 | U12: =1-$Q$12/$S$12*$M$24 | V12: =$Q$12*12 | X12: =1-($Q$12/$S$12)/($Q$9/$S$9) | Y12: =$S$12/$Q$12 | Z12: =$Q$12/$S$12*1000 | AB12: =$Q$12-$C$12
A13: =$A$27 | B13: 首月 | C13: =$D$27 | D13: =$C$13/$M$23 | E13: =$B$27 | F13: =$D$13/$E$13 | G13: =1-$C$13/$E$13*$M$24 | J13: =1-($C$13/$E$13)/($C$10/$E$10) | K13: =$E$13/$C$13 | L13: =$C$13/$E$13*1000 | O13: =$A$27 | P13: 首月 | Q13: =$D$27+$G$27 | R13: =$Q$13/$M$23 | S13: =$B$27 | T13: =$R$13/$S$13 | U13: =1-$Q$13/$S$13*$M$24 | X13: =1-($Q$13/$S$13)/($Q$10/$S$10) | Y13: =$S$13/$Q$13 | Z13: =$Q$13/$S$13*1000 | AB13: =$Q$13-$C$13
A14: =$A$27 | B14: 年（折合月价） | C14: =$E$27 | D14: =$C$14/$M$23 | E14: =$B$27 | F14: =$D$14/$E$14 | G14: =1-$C$14/$E$14*$M$24 | H14: =$C$14*12 | I14: =1-$C$14/$C$12 | J14: =1-($C$14/$E$14)/($C$11/$E$11) | K14: =$E$14/$C$14 | L14: =$C$14/$E$14*1000 | M14: =$E$14*12 | O14: =$A$27 | P14: 年（折合月价） | Q14: =$E$27+$H$27 | R14: =$Q$14/$M$23 | S14: =$B$27 | T14: =$R$14/$S$14 | U14: =1-$Q$14/$S$14*$M$24 | V14: =$Q$14*12 | W14: =1-$Q$14/$Q$12 | X14: =1-($Q$14/$S$14)/($Q$11/$S$11) | Y14: =$S$14/$Q$14 | Z14: =$Q$14/$S$14*1000 | AA14: =$S$14*12 | AB14: =$Q$14-$C$14
A16: 年行价格＝全年实付÷12；月均积分按月发放。年度总积分不代表一次到账。 | O16: 专业版单位积分与积分/元按整包价格计算，含专业能力，仅作套餐价值比较。
A17: 全年金额：月行是常规月购×12的比较值；年行是全年实付；首月行留空。 | O17: 年购优惠仅与12个月常规月购比较，不与首月价比较；不包含充值赠送或活动。
A18: 相邻档位优惠按同计费方式的单位积分价格比较；入门留空。节省为负表示更贵。 | O18: 专业能力价差用于价格对照，不直接等同于升级订单的软件实付折抵。
A20: 参数区为本表唯一输入来源；修改价格、额度或专业加价，主表自动联动。此表独立推演，不替换既有价格与权益。
A22: 可编辑参数｜基础价格与专业能力加价 | J22: 比较参数｜可编辑，非正式报价确认
A23: 档位 | B23: 每月积分 | C23: 基础常规月价 | D23: 基础首月价 | E23: 基础年购月均 | F23: 专业月购加价 | G23: 专业首月加价 | H23: 专业年购月均加价 | J23: 人民币/美元 | M23: 6.8 | N23: 沿参考图，仅用于换算对照
A24: 入门 | B24: 1000 | C24: 49 | D24: 39 | E24: 35 | F24: 151 | G24: 150 | H24: 125 | J24: 充值基准（积分/元） | M24: 20 | N24: 比较假设；不代表正式充值报价
A25: 轻量 | B25: 3000 | C25: 129 | D25: 99 | E25: 99 | F25: 150 | G25: 150 | H25: 120
A26: 标准 | B26: 7000 | C26: 299 | D26: 239 | E26: 199 | F26: 150 | G26: 150 | H26: 100 | J26: 首月仅适用于符合条件的首次购买；本表不替代首购资格及活动规则。
A27: 旗舰 | B27: 16000 | C27: 649 | D27: 529 | E27: 399 | F27: 150 | G27: 150 | H27: 100 | J27: 金额、数量保留完整计算精度；显示金额2位、单位价格4位、折扣2位小数。
A30: 核对摘要｜年购价格、优惠及积分均价
A31: 档位 | B31: 月均积分 | C31: 基础年费 | D31: 专业年费 | E31: 基础年购省 | F31: 专业年购省 | G31: 基础年购积分/元 | H31: 专业年购积分/元
A32: =$A$5 | B32: =$E$5 | C32: =$H$5 | D32: =$V$5 | E32: =$I$5 | F32: =$W$5 | G32: =$K$5 | H32: =$Y$5
A33: =$A$8 | B33: =$E$8 | C33: =$H$8 | D33: =$V$8 | E33: =$I$8 | F33: =$W$8 | G33: =$K$8 | H33: =$Y$8
A34: =$A$11 | B34: =$E$11 | C34: =$H$11 | D34: =$V$11 | E34: =$I$11 | F34: =$W$11 | G34: =$K$11 | H34: =$Y$11
A35: =$A$14 | B35: =$E$14 | C35: =$H$14 | D35: =$V$14 | E35: =$I$14 | F35: =$W$14 | G35: =$K$14 | H35: =$Y$14
